[warning] Static directory not found, static files will not be served
INFO:     Started server process [1145]
INFO:     Waiting for application startup.
[startup] Initializing Telegram bot...
[startup] Starting Telegram bot polling (attempt 1/3)...
[startup] Telegram bot polling started successfully
INFO:     Application startup complete.
INFO:     Uvicorn running on http://0.0.0.0:8002 (Press CTRL+C to quit)
Exception happened while polling for updates.
Traceback (most recent call last):
  File "/root/.venv/lib/python3.11/site-packages/telegram/ext/_updater.py", line 750, in _network_loop_retry
    if not await do_action():
           ^^^^^^^^^^^^^^^^^
  File "/root/.venv/lib/python3.11/site-packages/telegram/ext/_updater.py", line 744, in do_action
    return action_cb_task.result()
           ^^^^^^^^^^^^^^^^^^^^^^^
  File "/root/.venv/lib/python3.11/site-packages/telegram/ext/_updater.py", line 371, in polling_action_cb
    updates = await self.bot.get_updates(
              ^^^^^^^^^^^^^^^^^^^^^^^^^^^
  File "/root/.venv/lib/python3.11/site-packages/telegram/ext/_extbot.py", line 650, in get_updates
    updates = await super().get_updates(
              ^^^^^^^^^^^^^^^^^^^^^^^^^^
  File "/root/.venv/lib/python3.11/site-packages/telegram/_bot.py", line 4480, in get_updates
    await self._post(
  File "/root/.venv/lib/python3.11/site-packages/telegram/_bot.py", line 619, in _post
    return await self._do_post(
           ^^^^^^^^^^^^^^^^^^^^
  File "/root/.venv/lib/python3.11/site-packages/telegram/ext/_extbot.py", line 354, in _do_post
    return await super()._do_post(
           ^^^^^^^^^^^^^^^^^^^^^^^
  File "/root/.venv/lib/python3.11/site-packages/telegram/_bot.py", line 648, in _do_post
    result = await request.post(
             ^^^^^^^^^^^^^^^^^^^
  File "/root/.venv/lib/python3.11/site-packages/telegram/request/_baserequest.py", line 202, in post
    result = await self._request_wrapper(
             ^^^^^^^^^^^^^^^^^^^^^^^^^^^^
  File "/root/.venv/lib/python3.11/site-packages/telegram/request/_baserequest.py", line 385, in _request_wrapper
    raise Conflict(message)
telegram.error.Conflict: Conflict: terminated by other getUpdates request; make sure that only one bot instance is running
INFO:     127.0.0.1:33148 - "GET /api/health HTTP/1.1" 200 OK
Exception happened while polling for updates.
Traceback (most recent call last):
  File "/root/.venv/lib/python3.11/site-packages/telegram/ext/_updater.py", line 750, in _network_loop_retry
    if not await do_action():
           ^^^^^^^^^^^^^^^^^
  File "/root/.venv/lib/python3.11/site-packages/telegram/ext/_updater.py", line 744, in do_action
    return action_cb_task.result()
           ^^^^^^^^^^^^^^^^^^^^^^^
  File "/root/.venv/lib/python3.11/site-packages/telegram/ext/_updater.py", line 371, in polling_action_cb
    updates = await self.bot.get_updates(
              ^^^^^^^^^^^^^^^^^^^^^^^^^^^
  File "/root/.venv/lib/python3.11/site-packages/telegram/ext/_extbot.py", line 650, in get_updates
    updates = await super().get_updates(
              ^^^^^^^^^^^^^^^^^^^^^^^^^^
  File "/root/.venv/lib/python3.11/site-packages/telegram/_bot.py", line 4480, in get_updates
    await self._post(
  File "/root/.venv/lib/python3.11/site-packages/telegram/_bot.py", line 619, in _post
    return await self._do_post(
           ^^^^^^^^^^^^^^^^^^^^
  File "/root/.venv/lib/python3.11/site-packages/telegram/ext/_extbot.py", line 354, in _do_post
    return await super()._do_post(
           ^^^^^^^^^^^^^^^^^^^^^^^
  File "/root/.venv/lib/python3.11/site-packages/telegram/_bot.py", line 648, in _do_post
    result = await request.post(
             ^^^^^^^^^^^^^^^^^^^
  File "/root/.venv/lib/python3.11/site-packages/telegram/request/_baserequest.py", line 202, in post
    result = await self._request_wrapper(
             ^^^^^^^^^^^^^^^^^^^^^^^^^^^^
  File "/root/.venv/lib/python3.11/site-packages/telegram/request/_baserequest.py", line 385, in _request_wrapper
    raise Conflict(message)
telegram.error.Conflict: Conflict: terminated by other getUpdates request; make sure that only one bot instance is running
Exception happened while polling for updates.
Traceback (most recent call last):
  File "/root/.venv/lib/python3.11/site-packages/telegram/ext/_updater.py", line 750, in _network_loop_retry
    if not await do_action():
           ^^^^^^^^^^^^^^^^^
  File "/root/.venv/lib/python3.11/site-packages/telegram/ext/_updater.py", line 744, in do_action
    return action_cb_task.result()
           ^^^^^^^^^^^^^^^^^^^^^^^
  File "/root/.venv/lib/python3.11/site-packages/telegram/ext/_updater.py", line 371, in polling_action_cb
    updates = await self.bot.get_updates(
              ^^^^^^^^^^^^^^^^^^^^^^^^^^^
  File "/root/.venv/lib/python3.11/site-packages/telegram/ext/_extbot.py", line 650, in get_updates
    updates = await super().get_updates(
              ^^^^^^^^^^^^^^^^^^^^^^^^^^
  File "/root/.venv/lib/python3.11/site-packages/telegram/_bot.py", line 4480, in get_updates
    await self._post(
  File "/root/.venv/lib/python3.11/site-packages/telegram/_bot.py", line 619, in _post
    return await self._do_post(
           ^^^^^^^^^^^^^^^^^^^^
  File "/root/.venv/lib/python3.11/site-packages/telegram/ext/_extbot.py", line 354, in _do_post
    return await super()._do_post(
           ^^^^^^^^^^^^^^^^^^^^^^^
  File "/root/.venv/lib/python3.11/site-packages/telegram/_bot.py", line 648, in _do_post
    result = await request.post(
             ^^^^^^^^^^^^^^^^^^^
  File "/root/.venv/lib/python3.11/site-packages/telegram/request/_baserequest.py", line 202, in post
    result = await self._request_wrapper(
             ^^^^^^^^^^^^^^^^^^^^^^^^^^^^
  File "/root/.venv/lib/python3.11/site-packages/telegram/request/_baserequest.py", line 385, in _request_wrapper
    raise Conflict(message)
telegram.error.Conflict: Conflict: terminated by other getUpdates request; make sure that only one bot instance is running
Exception happened while polling for updates.
Traceback (most recent call last):
  File "/root/.venv/lib/python3.11/site-packages/telegram/ext/_updater.py", line 750, in _network_loop_retry
    if not await do_action():
           ^^^^^^^^^^^^^^^^^
  File "/root/.venv/lib/python3.11/site-packages/telegram/ext/_updater.py", line 744, in do_action
    return action_cb_task.result()
           ^^^^^^^^^^^^^^^^^^^^^^^
  File "/root/.venv/lib/python3.11/site-packages/telegram/ext/_updater.py", line 371, in polling_action_cb
    updates = await self.bot.get_updates(
              ^^^^^^^^^^^^^^^^^^^^^^^^^^^
  File "/root/.venv/lib/python3.11/site-packages/telegram/ext/_extbot.py", line 650, in get_updates
    updates = await super().get_updates(
              ^^^^^^^^^^^^^^^^^^^^^^^^^^
  File "/root/.venv/lib/python3.11/site-packages/telegram/_bot.py", line 4480, in get_updates
    await self._post(
  File "/root/.venv/lib/python3.11/site-packages/telegram/_bot.py", line 619, in _post
    return await self._do_post(
           ^^^^^^^^^^^^^^^^^^^^
  File "/root/.venv/lib/python3.11/site-packages/telegram/ext/_extbot.py", line 354, in _do_post
    return await super()._do_post(
           ^^^^^^^^^^^^^^^^^^^^^^^
  File "/root/.venv/lib/python3.11/site-packages/telegram/_bot.py", line 648, in _do_post
    result = await request.post(
             ^^^^^^^^^^^^^^^^^^^
  File "/root/.venv/lib/python3.11/site-packages/telegram/request/_baserequest.py", line 202, in post
    result = await self._request_wrapper(
             ^^^^^^^^^^^^^^^^^^^^^^^^^^^^
  File "/root/.venv/lib/python3.11/site-packages/telegram/request/_baserequest.py", line 385, in _request_wrapper
    raise Conflict(message)
telegram.error.Conflict: Conflict: terminated by other getUpdates request; make sure that only one bot instance is running
Exception happened while polling for updates.
Traceback (most recent call last):
  File "/root/.venv/lib/python3.11/site-packages/telegram/ext/_updater.py", line 750, in _network_loop_retry
    if not await do_action():
           ^^^^^^^^^^^^^^^^^
  File "/root/.venv/lib/python3.11/site-packages/telegram/ext/_updater.py", line 744, in do_action
    return action_cb_task.result()
           ^^^^^^^^^^^^^^^^^^^^^^^
  File "/root/.venv/lib/python3.11/site-packages/telegram/ext/_updater.py", line 371, in polling_action_cb
    updates = await self.bot.get_updates(
              ^^^^^^^^^^^^^^^^^^^^^^^^^^^
  File "/root/.venv/lib/python3.11/site-packages/telegram/ext/_extbot.py", line 650, in get_updates
    updates = await super().get_updates(
              ^^^^^^^^^^^^^^^^^^^^^^^^^^
  File "/root/.venv/lib/python3.11/site-packages/telegram/_bot.py", line 4480, in get_updates
    await self._post(
  File "/root/.venv/lib/python3.11/site-packages/telegram/_bot.py", line 619, in _post
    return await self._do_post(
           ^^^^^^^^^^^^^^^^^^^^
  File "/root/.venv/lib/python3.11/site-packages/telegram/ext/_extbot.py", line 354, in _do_post
    return await super()._do_post(
           ^^^^^^^^^^^^^^^^^^^^^^^
  File "/root/.venv/lib/python3.11/site-packages/telegram/_bot.py", line 648, in _do_post
    result = await request.post(
             ^^^^^^^^^^^^^^^^^^^
  File "/root/.venv/lib/python3.11/site-packages/telegram/request/_baserequest.py", line 202, in post
    result = await self._request_wrapper(
             ^^^^^^^^^^^^^^^^^^^^^^^^^^^^
  File "/root/.venv/lib/python3.11/site-packages/telegram/request/_baserequest.py", line 385, in _request_wrapper
    raise Conflict(message)
telegram.error.Conflict: Conflict: terminated by other getUpdates request; make sure that only one bot instance is running
Exception happened while polling for updates.
Traceback (most recent call last):
  File "/root/.venv/lib/python3.11/site-packages/telegram/ext/_updater.py", line 750, in _network_loop_retry
    if not await do_action():
           ^^^^^^^^^^^^^^^^^
  File "/root/.venv/lib/python3.11/site-packages/telegram/ext/_updater.py", line 744, in do_action
    return action_cb_task.result()
           ^^^^^^^^^^^^^^^^^^^^^^^
  File "/root/.venv/lib/python3.11/site-packages/telegram/ext/_updater.py", line 371, in polling_action_cb
    updates = await self.bot.get_updates(
              ^^^^^^^^^^^^^^^^^^^^^^^^^^^
  File "/root/.venv/lib/python3.11/site-packages/telegram/ext/_extbot.py", line 650, in get_updates
    updates = await super().get_updates(
              ^^^^^^^^^^^^^^^^^^^^^^^^^^
  File "/root/.venv/lib/python3.11/site-packages/telegram/_bot.py", line 4480, in get_updates
    await self._post(
  File "/root/.venv/lib/python3.11/site-packages/telegram/_bot.py", line 619, in _post
    return await self._do_post(
           ^^^^^^^^^^^^^^^^^^^^
  File "/root/.venv/lib/python3.11/site-packages/telegram/ext/_extbot.py", line 354, in _do_post
    return await super()._do_post(
           ^^^^^^^^^^^^^^^^^^^^^^^
  File "/root/.venv/lib/python3.11/site-packages/telegram/_bot.py", line 648, in _do_post
    result = await request.post(
             ^^^^^^^^^^^^^^^^^^^
  File "/root/.venv/lib/python3.11/site-packages/telegram/request/_baserequest.py", line 202, in post
    result = await self._request_wrapper(
             ^^^^^^^^^^^^^^^^^^^^^^^^^^^^
  File "/root/.venv/lib/python3.11/site-packages/telegram/request/_baserequest.py", line 385, in _request_wrapper
    raise Conflict(message)
telegram.error.Conflict: Conflict: terminated by other getUpdates request; make sure that only one bot instance is running
Exception happened while polling for updates.
Traceback (most recent call last):
  File "/root/.venv/lib/python3.11/site-packages/telegram/ext/_updater.py", line 750, in _network_loop_retry
    if not await do_action():
           ^^^^^^^^^^^^^^^^^
  File "/root/.venv/lib/python3.11/site-packages/telegram/ext/_updater.py", line 744, in do_action
    return action_cb_task.result()
           ^^^^^^^^^^^^^^^^^^^^^^^
  File "/root/.venv/lib/python3.11/site-packages/telegram/ext/_updater.py", line 371, in polling_action_cb
    updates = await self.bot.get_updates(
              ^^^^^^^^^^^^^^^^^^^^^^^^^^^
  File "/root/.venv/lib/python3.11/site-packages/telegram/ext/_extbot.py", line 650, in get_updates
    updates = await super().get_updates(
              ^^^^^^^^^^^^^^^^^^^^^^^^^^
  File "/root/.venv/lib/python3.11/site-packages/telegram/_bot.py", line 4480, in get_updates
    await self._post(
  File "/root/.venv/lib/python3.11/site-packages/telegram/_bot.py", line 619, in _post
    return await self._do_post(
           ^^^^^^^^^^^^^^^^^^^^
  File "/root/.venv/lib/python3.11/site-packages/telegram/ext/_extbot.py", line 354, in _do_post
    return await super()._do_post(
           ^^^^^^^^^^^^^^^^^^^^^^^
  File "/root/.venv/lib/python3.11/site-packages/telegram/_bot.py", line 648, in _do_post
    result = await request.post(
             ^^^^^^^^^^^^^^^^^^^
  File "/root/.venv/lib/python3.11/site-packages/telegram/request/_baserequest.py", line 202, in post
    result = await self._request_wrapper(
             ^^^^^^^^^^^^^^^^^^^^^^^^^^^^
  File "/root/.venv/lib/python3.11/site-packages/telegram/request/_baserequest.py", line 385, in _request_wrapper
    raise Conflict(message)
telegram.error.Conflict: Conflict: terminated by other getUpdates request; make sure that only one bot instance is running
Exception happened while polling for updates.
Traceback (most recent call last):
  File "/root/.venv/lib/python3.11/site-packages/telegram/ext/_updater.py", line 750, in _network_loop_retry
    if not await do_action():
           ^^^^^^^^^^^^^^^^^
  File "/root/.venv/lib/python3.11/site-packages/telegram/ext/_updater.py", line 744, in do_action
    return action_cb_task.result()
           ^^^^^^^^^^^^^^^^^^^^^^^
  File "/root/.venv/lib/python3.11/site-packages/telegram/ext/_updater.py", line 371, in polling_action_cb
    updates = await self.bot.get_updates(
              ^^^^^^^^^^^^^^^^^^^^^^^^^^^
  File "/root/.venv/lib/python3.11/site-packages/telegram/ext/_extbot.py", line 650, in get_updates
    updates = await super().get_updates(
              ^^^^^^^^^^^^^^^^^^^^^^^^^^
  File "/root/.venv/lib/python3.11/site-packages/telegram/_bot.py", line 4480, in get_updates
    await self._post(
  File "/root/.venv/lib/python3.11/site-packages/telegram/_bot.py", line 619, in _post
    return await self._do_post(
           ^^^^^^^^^^^^^^^^^^^^
  File "/root/.venv/lib/python3.11/site-packages/telegram/ext/_extbot.py", line 354, in _do_post
    return await super()._do_post(
           ^^^^^^^^^^^^^^^^^^^^^^^
  File "/root/.venv/lib/python3.11/site-packages/telegram/_bot.py", line 648, in _do_post
    result = await request.post(
             ^^^^^^^^^^^^^^^^^^^
  File "/root/.venv/lib/python3.11/site-packages/telegram/request/_baserequest.py", line 202, in post
    result = await self._request_wrapper(
             ^^^^^^^^^^^^^^^^^^^^^^^^^^^^
  File "/root/.venv/lib/python3.11/site-packages/telegram/request/_baserequest.py", line 385, in _request_wrapper
    raise Conflict(message)
telegram.error.Conflict: Conflict: terminated by other getUpdates request; make sure that only one bot instance is running
Exception happened while polling for updates.
Traceback (most recent call last):
  File "/root/.venv/lib/python3.11/site-packages/telegram/ext/_updater.py", line 750, in _network_loop_retry
    if not await do_action():
           ^^^^^^^^^^^^^^^^^
  File "/root/.venv/lib/python3.11/site-packages/telegram/ext/_updater.py", line 744, in do_action
    return action_cb_task.result()
           ^^^^^^^^^^^^^^^^^^^^^^^
  File "/root/.venv/lib/python3.11/site-packages/telegram/ext/_updater.py", line 371, in polling_action_cb
    updates = await self.bot.get_updates(
              ^^^^^^^^^^^^^^^^^^^^^^^^^^^
  File "/root/.venv/lib/python3.11/site-packages/telegram/ext/_extbot.py", line 650, in get_updates
    updates = await super().get_updates(
              ^^^^^^^^^^^^^^^^^^^^^^^^^^
  File "/root/.venv/lib/python3.11/site-packages/telegram/_bot.py", line 4480, in get_updates
    await self._post(
  File "/root/.venv/lib/python3.11/site-packages/telegram/_bot.py", line 619, in _post
    return await self._do_post(
           ^^^^^^^^^^^^^^^^^^^^
  File "/root/.venv/lib/python3.11/site-packages/telegram/ext/_extbot.py", line 354, in _do_post
    return await super()._do_post(
           ^^^^^^^^^^^^^^^^^^^^^^^
  File "/root/.venv/lib/python3.11/site-packages/telegram/_bot.py", line 648, in _do_post
    result = await request.post(
             ^^^^^^^^^^^^^^^^^^^
  File "/root/.venv/lib/python3.11/site-packages/telegram/request/_baserequest.py", line 202, in post
    result = await self._request_wrapper(
             ^^^^^^^^^^^^^^^^^^^^^^^^^^^^
  File "/root/.venv/lib/python3.11/site-packages/telegram/request/_baserequest.py", line 385, in _request_wrapper
    raise Conflict(message)
telegram.error.Conflict: Conflict: terminated by other getUpdates request; make sure that only one bot instance is running
INFO:     127.0.0.1:46800 - "GET /api/stats/summary HTTP/1.1" 200 OK
INFO:     127.0.0.1:46808 - "GET /api/tasks HTTP/1.1" 200 OK
INFO:     127.0.0.1:33634 - "GET / HTTP/1.1" 500 Internal Server Error
ERROR:    Exception in ASGI application
Traceback (most recent call last):
  File "/root/.venv/lib/python3.11/site-packages/uvicorn/protocols/http/h11_impl.py", line 408, in run_asgi
    result = await app(  # type: ignore[func-returns-value]
             ^^^^^^^^^^^^^^^^^^^^^^^^^^^^^^^^^^^^^^^^^^^^^^
  File "/root/.venv/lib/python3.11/site-packages/uvicorn/middleware/proxy_headers.py", line 84, in __call__
    return await self.app(scope, receive, send)
           ^^^^^^^^^^^^^^^^^^^^^^^^^^^^^^^^^^^^
  File "/root/.venv/lib/python3.11/site-packages/fastapi/applications.py", line 1054, in __call__
    await super().__call__(scope, receive, send)
  File "/root/.venv/lib/python3.11/site-packages/starlette/applications.py", line 123, in __call__
    await self.middleware_stack(scope, receive, send)
  File "/root/.venv/lib/python3.11/site-packages/starlette/middleware/errors.py", line 186, in __call__
    raise exc
  File "/root/.venv/lib/python3.11/site-packages/starlette/middleware/errors.py", line 164, in __call__
    await self.app(scope, receive, _send)
  File "/root/.venv/lib/python3.11/site-packages/starlette/middleware/cors.py", line 85, in __call__
    await self.app(scope, receive, send)
  File "/root/.venv/lib/python3.11/site-packages/starlette/middleware/exceptions.py", line 65, in __call__
    await wrap_app_handling_exceptions(self.app, conn)(scope, receive, send)
  File "/root/.venv/lib/python3.11/site-packages/starlette/_exception_handler.py", line 64, in wrapped_app
    raise exc
  File "/root/.venv/lib/python3.11/site-packages/starlette/_exception_handler.py", line 53, in wrapped_app
    await app(scope, receive, sender)
  File "/root/.venv/lib/python3.11/site-packages/starlette/routing.py", line 756, in __call__
    await self.middleware_stack(scope, receive, send)
  File "/root/.venv/lib/python3.11/site-packages/starlette/routing.py", line 776, in app
    await route.handle(scope, receive, send)
  File "/root/.venv/lib/python3.11/site-packages/starlette/routing.py", line 297, in handle
    await self.app(scope, receive, send)
  File "/root/.venv/lib/python3.11/site-packages/starlette/routing.py", line 77, in app
    await wrap_app_handling_exceptions(app, request)(scope, receive, send)
  File "/root/.venv/lib/python3.11/site-packages/starlette/_exception_handler.py", line 64, in wrapped_app
    raise exc
  File "/root/.venv/lib/python3.11/site-packages/starlette/_exception_handler.py", line 53, in wrapped_app
    await app(scope, receive, sender)
  File "/root/.venv/lib/python3.11/site-packages/starlette/routing.py", line 72, in app
    response = await func(request)
               ^^^^^^^^^^^^^^^^^^^
  File "/root/.venv/lib/python3.11/site-packages/fastapi/routing.py", line 278, in app
    raw_response = await run_endpoint_function(
                   ^^^^^^^^^^^^^^^^^^^^^^^^^^^^
  File "/root/.venv/lib/python3.11/site-packages/fastapi/routing.py", line 191, in run_endpoint_function
    return await dependant.call(**values)
           ^^^^^^^^^^^^^^^^^^^^^^^^^^^^^^
  File "/app/12-vfd/backend/server.py", line 462, in dashboard
    return templates.TemplateResponse("dashboard.html", {
           ^^^^^^^^^^^^^^^^^^^^^^^^^^^^^^^^^^^^^^^^^^^^^^
  File "/root/.venv/lib/python3.11/site-packages/starlette/templating.py", line 229, in TemplateResponse
    template = self.get_template(name)
               ^^^^^^^^^^^^^^^^^^^^^^^
  File "/root/.venv/lib/python3.11/site-packages/starlette/templating.py", line 143, in get_template
    return self.env.get_template(name)
           ^^^^^^^^^^^^^^^^^^^^^^^^^^^
  File "/root/.venv/lib/python3.11/site-packages/jinja2/environment.py", line 1016, in get_template
    return self._load_template(name, globals)
           ^^^^^^^^^^^^^^^^^^^^^^^^^^^^^^^^^^
  File "/root/.venv/lib/python3.11/site-packages/jinja2/environment.py", line 975, in _load_template
    template = self.loader.load(self, name, self.make_globals(globals))
               ^^^^^^^^^^^^^^^^^^^^^^^^^^^^^^^^^^^^^^^^^^^^^^^^^^^^^^^^
  File "/root/.venv/lib/python3.11/site-packages/jinja2/loaders.py", line 126, in load
    source, filename, uptodate = self.get_source(environment, name)
                                 ^^^^^^^^^^^^^^^^^^^^^^^^^^^^^^^^^^
  File "/root/.venv/lib/python3.11/site-packages/jinja2/loaders.py", line 209, in get_source
    raise TemplateNotFound(
jinja2.exceptions.TemplateNotFound: 'dashboard.html' not found in search path: 'templates'
Exception happened while polling for updates.
Traceback (most recent call last):
  File "/root/.venv/lib/python3.11/site-packages/telegram/ext/_updater.py", line 750, in _network_loop_retry
    if not await do_action():
           ^^^^^^^^^^^^^^^^^
  File "/root/.venv/lib/python3.11/site-packages/telegram/ext/_updater.py", line 744, in do_action
    return action_cb_task.result()
           ^^^^^^^^^^^^^^^^^^^^^^^
  File "/root/.venv/lib/python3.11/site-packages/telegram/ext/_updater.py", line 371, in polling_action_cb
    updates = await self.bot.get_updates(
              ^^^^^^^^^^^^^^^^^^^^^^^^^^^
  File "/root/.venv/lib/python3.11/site-packages/telegram/ext/_extbot.py", line 650, in get_updates
    updates = await super().get_updates(
              ^^^^^^^^^^^^^^^^^^^^^^^^^^
  File "/root/.venv/lib/python3.11/site-packages/telegram/_bot.py", line 4480, in get_updates
    await self._post(
  File "/root/.venv/lib/python3.11/site-packages/telegram/_bot.py", line 619, in _post
    return await self._do_post(
           ^^^^^^^^^^^^^^^^^^^^
  File "/root/.venv/lib/python3.11/site-packages/telegram/ext/_extbot.py", line 354, in _do_post
    return await super()._do_post(
           ^^^^^^^^^^^^^^^^^^^^^^^
  File "/root/.venv/lib/python3.11/site-packages/telegram/_bot.py", line 648, in _do_post
    result = await request.post(
             ^^^^^^^^^^^^^^^^^^^
  File "/root/.venv/lib/python3.11/site-packages/telegram/request/_baserequest.py", line 202, in post
    result = await self._request_wrapper(
             ^^^^^^^^^^^^^^^^^^^^^^^^^^^^
  File "/root/.venv/lib/python3.11/site-packages/telegram/request/_baserequest.py", line 385, in _request_wrapper
    raise Conflict(message)
telegram.error.Conflict: Conflict: terminated by other getUpdates request; make sure that only one bot instance is running
INFO:     127.0.0.1:34100 - "GET / HTTP/1.1" 500 Internal Server Error
ERROR:    Exception in ASGI application
Traceback (most recent call last):
  File "/root/.venv/lib/python3.11/site-packages/uvicorn/protocols/http/h11_impl.py", line 408, in run_asgi
    result = await app(  # type: ignore[func-returns-value]
             ^^^^^^^^^^^^^^^^^^^^^^^^^^^^^^^^^^^^^^^^^^^^^^
  File "/root/.venv/lib/python3.11/site-packages/uvicorn/middleware/proxy_headers.py", line 84, in __call__
    return await self.app(scope, receive, send)
           ^^^^^^^^^^^^^^^^^^^^^^^^^^^^^^^^^^^^
  File "/root/.venv/lib/python3.11/site-packages/fastapi/applications.py", line 1054, in __call__
    await super().__call__(scope, receive, send)
  File "/root/.venv/lib/python3.11/site-packages/starlette/applications.py", line 123, in __call__
    await self.middleware_stack(scope, receive, send)
  File "/root/.venv/lib/python3.11/site-packages/starlette/middleware/errors.py", line 186, in __call__
    raise exc
  File "/root/.venv/lib/python3.11/site-packages/starlette/middleware/errors.py", line 164, in __call__
    await self.app(scope, receive, _send)
  File "/root/.venv/lib/python3.11/site-packages/starlette/middleware/cors.py", line 85, in __call__
    await self.app(scope, receive, send)
  File "/root/.venv/lib/python3.11/site-packages/starlette/middleware/exceptions.py", line 65, in __call__
    await wrap_app_handling_exceptions(self.app, conn)(scope, receive, send)
  File "/root/.venv/lib/python3.11/site-packages/starlette/_exception_handler.py", line 64, in wrapped_app
    raise exc
  File "/root/.venv/lib/python3.11/site-packages/starlette/_exception_handler.py", line 53, in wrapped_app
    await app(scope, receive, sender)
  File "/root/.venv/lib/python3.11/site-packages/starlette/routing.py", line 756, in __call__
    await self.middleware_stack(scope, receive, send)
  File "/root/.venv/lib/python3.11/site-packages/starlette/routing.py", line 776, in app
    await route.handle(scope, receive, send)
  File "/root/.venv/lib/python3.11/site-packages/starlette/routing.py", line 297, in handle
    await self.app(scope, receive, send)
  File "/root/.venv/lib/python3.11/site-packages/starlette/routing.py", line 77, in app
    await wrap_app_handling_exceptions(app, request)(scope, receive, send)
  File "/root/.venv/lib/python3.11/site-packages/starlette/_exception_handler.py", line 64, in wrapped_app
    raise exc
  File "/root/.venv/lib/python3.11/site-packages/starlette/_exception_handler.py", line 53, in wrapped_app
    await app(scope, receive, sender)
  File "/root/.venv/lib/python3.11/site-packages/starlette/routing.py", line 72, in app
    response = await func(request)
               ^^^^^^^^^^^^^^^^^^^
  File "/root/.venv/lib/python3.11/site-packages/fastapi/routing.py", line 278, in app
    raw_response = await run_endpoint_function(
                   ^^^^^^^^^^^^^^^^^^^^^^^^^^^^
  File "/root/.venv/lib/python3.11/site-packages/fastapi/routing.py", line 191, in run_endpoint_function
    return await dependant.call(**values)
           ^^^^^^^^^^^^^^^^^^^^^^^^^^^^^^
  File "/app/12-vfd/backend/server.py", line 462, in dashboard
    return templates.TemplateResponse("dashboard.html", {
           ^^^^^^^^^^^^^^^^^^^^^^^^^^^^^^^^^^^^^^^^^^^^^^
  File "/root/.venv/lib/python3.11/site-packages/starlette/templating.py", line 229, in TemplateResponse
    template = self.get_template(name)
               ^^^^^^^^^^^^^^^^^^^^^^^
  File "/root/.venv/lib/python3.11/site-packages/starlette/templating.py", line 143, in get_template
    return self.env.get_template(name)
           ^^^^^^^^^^^^^^^^^^^^^^^^^^^
  File "/root/.venv/lib/python3.11/site-packages/jinja2/environment.py", line 1016, in get_template
    return self._load_template(name, globals)
           ^^^^^^^^^^^^^^^^^^^^^^^^^^^^^^^^^^
  File "/root/.venv/lib/python3.11/site-packages/jinja2/environment.py", line 975, in _load_template
    template = self.loader.load(self, name, self.make_globals(globals))
               ^^^^^^^^^^^^^^^^^^^^^^^^^^^^^^^^^^^^^^^^^^^^^^^^^^^^^^^^
  File "/root/.venv/lib/python3.11/site-packages/jinja2/loaders.py", line 126, in load
    source, filename, uptodate = self.get_source(environment, name)
                                 ^^^^^^^^^^^^^^^^^^^^^^^^^^^^^^^^^^
  File "/root/.venv/lib/python3.11/site-packages/jinja2/loaders.py", line 209, in get_source
    raise TemplateNotFound(
jinja2.exceptions.TemplateNotFound: 'dashboard.html' not found in search path: 'templates'
Exception happened while polling for updates.
Traceback (most recent call last):
  File "/root/.venv/lib/python3.11/site-packages/telegram/ext/_updater.py", line 750, in _network_loop_retry
    if not await do_action():
           ^^^^^^^^^^^^^^^^^
  File "/root/.venv/lib/python3.11/site-packages/telegram/ext/_updater.py", line 744, in do_action
    return action_cb_task.result()
           ^^^^^^^^^^^^^^^^^^^^^^^
  File "/root/.venv/lib/python3.11/site-packages/telegram/ext/_updater.py", line 371, in polling_action_cb
    updates = await self.bot.get_updates(
              ^^^^^^^^^^^^^^^^^^^^^^^^^^^
  File "/root/.venv/lib/python3.11/site-packages/telegram/ext/_extbot.py", line 650, in get_updates
    updates = await super().get_updates(
              ^^^^^^^^^^^^^^^^^^^^^^^^^^
  File "/root/.venv/lib/python3.11/site-packages/telegram/_bot.py", line 4480, in get_updates
    await self._post(
  File "/root/.venv/lib/python3.11/site-packages/telegram/_bot.py", line 619, in _post
    return await self._do_post(
           ^^^^^^^^^^^^^^^^^^^^
  File "/root/.venv/lib/python3.11/site-packages/telegram/ext/_extbot.py", line 354, in _do_post
    return await super()._do_post(
           ^^^^^^^^^^^^^^^^^^^^^^^
  File "/root/.venv/lib/python3.11/site-packages/telegram/_bot.py", line 648, in _do_post
    result = await request.post(
             ^^^^^^^^^^^^^^^^^^^
  File "/root/.venv/lib/python3.11/site-packages/telegram/request/_baserequest.py", line 202, in post
    result = await self._request_wrapper(
             ^^^^^^^^^^^^^^^^^^^^^^^^^^^^
  File "/root/.venv/lib/python3.11/site-packages/telegram/request/_baserequest.py", line 385, in _request_wrapper
    raise Conflict(message)
telegram.error.Conflict: Conflict: terminated by other getUpdates request; make sure that only one bot instance is running
INFO:     Shutting down
INFO:     Waiting for application shutdown.
[shutdown] Stopping Telegram bot...
[shutdown] Telegram bot stopped successfully
[shutdown] MongoDB connection closed
INFO:     Application shutdown complete.
INFO:     Finished server process [1145]
