INFO:     Started server process [1946]
INFO:     Waiting for application startup.
[startup] Initializing Telegram bot...
[startup] Starting Telegram bot polling (attempt 1/3)...
[startup] Telegram bot polling started successfully
INFO:     Application startup complete.
INFO:     Uvicorn running on http://0.0.0.0:8002 (Press CTRL+C to quit)
Exception happened while polling for updates.
Traceback (most recent call last):
  File "/root/.venv/lib/python3.11/site-packages/telegram/ext/_updater.py", line 750, in _network_loop_retry
    if not await do_action():
           ^^^^^^^^^^^^^^^^^
  File "/root/.venv/lib/python3.11/site-packages/telegram/ext/_updater.py", line 744, in do_action
    return action_cb_task.result()
           ^^^^^^^^^^^^^^^^^^^^^^^
  File "/root/.venv/lib/python3.11/site-packages/telegram/ext/_updater.py", line 371, in polling_action_cb
    updates = await self.bot.get_updates(
              ^^^^^^^^^^^^^^^^^^^^^^^^^^^
  File "/root/.venv/lib/python3.11/site-packages/telegram/ext/_extbot.py", line 650, in get_updates
    updates = await super().get_updates(
              ^^^^^^^^^^^^^^^^^^^^^^^^^^
  File "/root/.venv/lib/python3.11/site-packages/telegram/_bot.py", line 4480, in get_updates
    await self._post(
  File "/root/.venv/lib/python3.11/site-packages/telegram/_bot.py", line 619, in _post
    return await self._do_post(
           ^^^^^^^^^^^^^^^^^^^^
  File "/root/.venv/lib/python3.11/site-packages/telegram/ext/_extbot.py", line 354, in _do_post
    return await super()._do_post(
           ^^^^^^^^^^^^^^^^^^^^^^^
  File "/root/.venv/lib/python3.11/site-packages/telegram/_bot.py", line 648, in _do_post
    result = await request.post(
             ^^^^^^^^^^^^^^^^^^^
  File "/root/.venv/lib/python3.11/site-packages/telegram/request/_baserequest.py", line 202, in post
    result = await self._request_wrapper(
             ^^^^^^^^^^^^^^^^^^^^^^^^^^^^
  File "/root/.venv/lib/python3.11/site-packages/telegram/request/_baserequest.py", line 385, in _request_wrapper
    raise Conflict(message)
telegram.error.Conflict: Conflict: terminated by other getUpdates request; make sure that only one bot instance is running
INFO:     127.0.0.1:32846 - "GET /api/health HTTP/1.1" 200 OK
INFO:     127.0.0.1:56280 - "GET / HTTP/1.1" 200 OK
Exception happened while polling for updates.
Traceback (most recent call last):
  File "/root/.venv/lib/python3.11/site-packages/telegram/ext/_updater.py", line 750, in _network_loop_retry
    if not await do_action():
           ^^^^^^^^^^^^^^^^^
  File "/root/.venv/lib/python3.11/site-packages/telegram/ext/_updater.py", line 744, in do_action
    return action_cb_task.result()
           ^^^^^^^^^^^^^^^^^^^^^^^
  File "/root/.venv/lib/python3.11/site-packages/telegram/ext/_updater.py", line 371, in polling_action_cb
    updates = await self.bot.get_updates(
              ^^^^^^^^^^^^^^^^^^^^^^^^^^^
  File "/root/.venv/lib/python3.11/site-packages/telegram/ext/_extbot.py", line 650, in get_updates
    updates = await super().get_updates(
              ^^^^^^^^^^^^^^^^^^^^^^^^^^
  File "/root/.venv/lib/python3.11/site-packages/telegram/_bot.py", line 4480, in get_updates
    await self._post(
  File "/root/.venv/lib/python3.11/site-packages/telegram/_bot.py", line 619, in _post
    return await self._do_post(
           ^^^^^^^^^^^^^^^^^^^^
  File "/root/.venv/lib/python3.11/site-packages/telegram/ext/_extbot.py", line 354, in _do_post
    return await super()._do_post(
           ^^^^^^^^^^^^^^^^^^^^^^^
  File "/root/.venv/lib/python3.11/site-packages/telegram/_bot.py", line 648, in _do_post
    result = await request.post(
             ^^^^^^^^^^^^^^^^^^^
  File "/root/.venv/lib/python3.11/site-packages/telegram/request/_baserequest.py", line 202, in post
    result = await self._request_wrapper(
             ^^^^^^^^^^^^^^^^^^^^^^^^^^^^
  File "/root/.venv/lib/python3.11/site-packages/telegram/request/_baserequest.py", line 385, in _request_wrapper
    raise Conflict(message)
telegram.error.Conflict: Conflict: terminated by other getUpdates request; make sure that only one bot instance is running
Exception happened while polling for updates.
Traceback (most recent call last):
  File "/root/.venv/lib/python3.11/site-packages/telegram/ext/_updater.py", line 750, in _network_loop_retry
    if not await do_action():
           ^^^^^^^^^^^^^^^^^
  File "/root/.venv/lib/python3.11/site-packages/telegram/ext/_updater.py", line 744, in do_action
    return action_cb_task.result()
           ^^^^^^^^^^^^^^^^^^^^^^^
  File "/root/.venv/lib/python3.11/site-packages/telegram/ext/_updater.py", line 371, in polling_action_cb
    updates = await self.bot.get_updates(
              ^^^^^^^^^^^^^^^^^^^^^^^^^^^
  File "/root/.venv/lib/python3.11/site-packages/telegram/ext/_extbot.py", line 650, in get_updates
    updates = await super().get_updates(
              ^^^^^^^^^^^^^^^^^^^^^^^^^^
  File "/root/.venv/lib/python3.11/site-packages/telegram/_bot.py", line 4480, in get_updates
    await self._post(
  File "/root/.venv/lib/python3.11/site-packages/telegram/_bot.py", line 619, in _post
    return await self._do_post(
           ^^^^^^^^^^^^^^^^^^^^
  File "/root/.venv/lib/python3.11/site-packages/telegram/ext/_extbot.py", line 354, in _do_post
    return await super()._do_post(
           ^^^^^^^^^^^^^^^^^^^^^^^
  File "/root/.venv/lib/python3.11/site-packages/telegram/_bot.py", line 648, in _do_post
    result = await request.post(
             ^^^^^^^^^^^^^^^^^^^
  File "/root/.venv/lib/python3.11/site-packages/telegram/request/_baserequest.py", line 202, in post
    result = await self._request_wrapper(
             ^^^^^^^^^^^^^^^^^^^^^^^^^^^^
  File "/root/.venv/lib/python3.11/site-packages/telegram/request/_baserequest.py", line 385, in _request_wrapper
    raise Conflict(message)
telegram.error.Conflict: Conflict: terminated by other getUpdates request; make sure that only one bot instance is running
Exception happened while polling for updates.
Traceback (most recent call last):
  File "/root/.venv/lib/python3.11/site-packages/telegram/ext/_updater.py", line 750, in _network_loop_retry
    if not await do_action():
           ^^^^^^^^^^^^^^^^^
  File "/root/.venv/lib/python3.11/site-packages/telegram/ext/_updater.py", line 744, in do_action
    return action_cb_task.result()
           ^^^^^^^^^^^^^^^^^^^^^^^
  File "/root/.venv/lib/python3.11/site-packages/telegram/ext/_updater.py", line 371, in polling_action_cb
    updates = await self.bot.get_updates(
              ^^^^^^^^^^^^^^^^^^^^^^^^^^^
  File "/root/.venv/lib/python3.11/site-packages/telegram/ext/_extbot.py", line 650, in get_updates
    updates = await super().get_updates(
              ^^^^^^^^^^^^^^^^^^^^^^^^^^
  File "/root/.venv/lib/python3.11/site-packages/telegram/_bot.py", line 4480, in get_updates
    await self._post(
  File "/root/.venv/lib/python3.11/site-packages/telegram/_bot.py", line 619, in _post
    return await self._do_post(
           ^^^^^^^^^^^^^^^^^^^^
  File "/root/.venv/lib/python3.11/site-packages/telegram/ext/_extbot.py", line 354, in _do_post
    return await super()._do_post(
           ^^^^^^^^^^^^^^^^^^^^^^^
  File "/root/.venv/lib/python3.11/site-packages/telegram/_bot.py", line 648, in _do_post
    result = await request.post(
             ^^^^^^^^^^^^^^^^^^^
  File "/root/.venv/lib/python3.11/site-packages/telegram/request/_baserequest.py", line 202, in post
    result = await self._request_wrapper(
             ^^^^^^^^^^^^^^^^^^^^^^^^^^^^
  File "/root/.venv/lib/python3.11/site-packages/telegram/request/_baserequest.py", line 385, in _request_wrapper
    raise Conflict(message)
telegram.error.Conflict: Conflict: terminated by other getUpdates request; make sure that only one bot instance is running
Exception happened while polling for updates.
Traceback (most recent call last):
  File "/root/.venv/lib/python3.11/site-packages/telegram/ext/_updater.py", line 750, in _network_loop_retry
    if not await do_action():
           ^^^^^^^^^^^^^^^^^
  File "/root/.venv/lib/python3.11/site-packages/telegram/ext/_updater.py", line 744, in do_action
    return action_cb_task.result()
           ^^^^^^^^^^^^^^^^^^^^^^^
  File "/root/.venv/lib/python3.11/site-packages/telegram/ext/_updater.py", line 371, in polling_action_cb
    updates = await self.bot.get_updates(
              ^^^^^^^^^^^^^^^^^^^^^^^^^^^
  File "/root/.venv/lib/python3.11/site-packages/telegram/ext/_extbot.py", line 650, in get_updates
    updates = await super().get_updates(
              ^^^^^^^^^^^^^^^^^^^^^^^^^^
  File "/root/.venv/lib/python3.11/site-packages/telegram/_bot.py", line 4480, in get_updates
    await self._post(
  File "/root/.venv/lib/python3.11/site-packages/telegram/_bot.py", line 619, in _post
    return await self._do_post(
           ^^^^^^^^^^^^^^^^^^^^
  File "/root/.venv/lib/python3.11/site-packages/telegram/ext/_extbot.py", line 354, in _do_post
    return await super()._do_post(
           ^^^^^^^^^^^^^^^^^^^^^^^
  File "/root/.venv/lib/python3.11/site-packages/telegram/_bot.py", line 648, in _do_post
    result = await request.post(
             ^^^^^^^^^^^^^^^^^^^
  File "/root/.venv/lib/python3.11/site-packages/telegram/request/_baserequest.py", line 202, in post
    result = await self._request_wrapper(
             ^^^^^^^^^^^^^^^^^^^^^^^^^^^^
  File "/root/.venv/lib/python3.11/site-packages/telegram/request/_baserequest.py", line 385, in _request_wrapper
    raise Conflict(message)
telegram.error.Conflict: Conflict: terminated by other getUpdates request; make sure that only one bot instance is running
No error handlers are registered, logging exception.
Traceback (most recent call last):
  File "/root/.venv/lib/python3.11/site-packages/telegram/ext/_application.py", line 1325, in process_update
    await coroutine
  File "/root/.venv/lib/python3.11/site-packages/telegram/ext/_handlers/conversationhandler.py", line 844, in handle_update
    new_state: object = await handler.handle_update(
                        ^^^^^^^^^^^^^^^^^^^^^^^^^^^^
  File "/root/.venv/lib/python3.11/site-packages/telegram/ext/_handlers/basehandler.py", line 158, in handle_update
    return await self.callback(update, context)
           ^^^^^^^^^^^^^^^^^^^^^^^^^^^^^^^^^^^^
  File "/app/12-vfd/backend/server.py", line 635, in cmd_start
    await update.message.reply_text(
  File "/root/.venv/lib/python3.11/site-packages/telegram/_message.py", line 1771, in reply_text
    return await self.get_bot().send_message(
           ^^^^^^^^^^^^^^^^^^^^^^^^^^^^^^^^^^
  File "/root/.venv/lib/python3.11/site-packages/telegram/ext/_extbot.py", line 2965, in send_message
    return await super().send_message(
           ^^^^^^^^^^^^^^^^^^^^^^^^^^^
  File "/root/.venv/lib/python3.11/site-packages/telegram/_bot.py", line 1019, in send_message
    return await self._send_message(
           ^^^^^^^^^^^^^^^^^^^^^^^^^
  File "/root/.venv/lib/python3.11/site-packages/telegram/ext/_extbot.py", line 610, in _send_message
    result = await super()._send_message(
             ^^^^^^^^^^^^^^^^^^^^^^^^^^^^
  File "/root/.venv/lib/python3.11/site-packages/telegram/_bot.py", line 731, in _send_message
    result = await self._post(
             ^^^^^^^^^^^^^^^^^
  File "/root/.venv/lib/python3.11/site-packages/telegram/_bot.py", line 619, in _post
    return await self._do_post(
           ^^^^^^^^^^^^^^^^^^^^
  File "/root/.venv/lib/python3.11/site-packages/telegram/ext/_extbot.py", line 354, in _do_post
    return await super()._do_post(
           ^^^^^^^^^^^^^^^^^^^^^^^
  File "/root/.venv/lib/python3.11/site-packages/telegram/_bot.py", line 648, in _do_post
    result = await request.post(
             ^^^^^^^^^^^^^^^^^^^
  File "/root/.venv/lib/python3.11/site-packages/telegram/request/_baserequest.py", line 202, in post
    result = await self._request_wrapper(
             ^^^^^^^^^^^^^^^^^^^^^^^^^^^^
  File "/root/.venv/lib/python3.11/site-packages/telegram/request/_baserequest.py", line 383, in _request_wrapper
    raise BadRequest(message)
telegram.error.BadRequest: Inline keyboard button web app url 'http://localhost:3000/webapp?user_id=d20d8497315c46e0a9675579e5028818' is invalid: only https links are allowed
Exception happened while polling for updates.
Traceback (most recent call last):
  File "/root/.venv/lib/python3.11/site-packages/telegram/ext/_updater.py", line 750, in _network_loop_retry
    if not await do_action():
           ^^^^^^^^^^^^^^^^^
  File "/root/.venv/lib/python3.11/site-packages/telegram/ext/_updater.py", line 744, in do_action
    return action_cb_task.result()
           ^^^^^^^^^^^^^^^^^^^^^^^
  File "/root/.venv/lib/python3.11/site-packages/telegram/ext/_updater.py", line 371, in polling_action_cb
    updates = await self.bot.get_updates(
              ^^^^^^^^^^^^^^^^^^^^^^^^^^^
  File "/root/.venv/lib/python3.11/site-packages/telegram/ext/_extbot.py", line 650, in get_updates
    updates = await super().get_updates(
              ^^^^^^^^^^^^^^^^^^^^^^^^^^
  File "/root/.venv/lib/python3.11/site-packages/telegram/_bot.py", line 4480, in get_updates
    await self._post(
  File "/root/.venv/lib/python3.11/site-packages/telegram/_bot.py", line 619, in _post
    return await self._do_post(
           ^^^^^^^^^^^^^^^^^^^^
  File "/root/.venv/lib/python3.11/site-packages/telegram/ext/_extbot.py", line 354, in _do_post
    return await super()._do_post(
           ^^^^^^^^^^^^^^^^^^^^^^^
  File "/root/.venv/lib/python3.11/site-packages/telegram/_bot.py", line 648, in _do_post
    result = await request.post(
             ^^^^^^^^^^^^^^^^^^^
  File "/root/.venv/lib/python3.11/site-packages/telegram/request/_baserequest.py", line 202, in post
    result = await self._request_wrapper(
             ^^^^^^^^^^^^^^^^^^^^^^^^^^^^
  File "/root/.venv/lib/python3.11/site-packages/telegram/request/_baserequest.py", line 385, in _request_wrapper
    raise Conflict(message)
telegram.error.Conflict: Conflict: terminated by other getUpdates request; make sure that only one bot instance is running
Exception happened while polling for updates.
Traceback (most recent call last):
  File "/root/.venv/lib/python3.11/site-packages/telegram/ext/_updater.py", line 750, in _network_loop_retry
    if not await do_action():
           ^^^^^^^^^^^^^^^^^
  File "/root/.venv/lib/python3.11/site-packages/telegram/ext/_updater.py", line 744, in do_action
    return action_cb_task.result()
           ^^^^^^^^^^^^^^^^^^^^^^^
  File "/root/.venv/lib/python3.11/site-packages/telegram/ext/_updater.py", line 371, in polling_action_cb
    updates = await self.bot.get_updates(
              ^^^^^^^^^^^^^^^^^^^^^^^^^^^
  File "/root/.venv/lib/python3.11/site-packages/telegram/ext/_extbot.py", line 650, in get_updates
    updates = await super().get_updates(
              ^^^^^^^^^^^^^^^^^^^^^^^^^^
  File "/root/.venv/lib/python3.11/site-packages/telegram/_bot.py", line 4480, in get_updates
    await self._post(
  File "/root/.venv/lib/python3.11/site-packages/telegram/_bot.py", line 619, in _post
    return await self._do_post(
           ^^^^^^^^^^^^^^^^^^^^
  File "/root/.venv/lib/python3.11/site-packages/telegram/ext/_extbot.py", line 354, in _do_post
    return await super()._do_post(
           ^^^^^^^^^^^^^^^^^^^^^^^
  File "/root/.venv/lib/python3.11/site-packages/telegram/_bot.py", line 648, in _do_post
    result = await request.post(
             ^^^^^^^^^^^^^^^^^^^
  File "/root/.venv/lib/python3.11/site-packages/telegram/request/_baserequest.py", line 202, in post
    result = await self._request_wrapper(
             ^^^^^^^^^^^^^^^^^^^^^^^^^^^^
  File "/root/.venv/lib/python3.11/site-packages/telegram/request/_baserequest.py", line 385, in _request_wrapper
    raise Conflict(message)
telegram.error.Conflict: Conflict: terminated by other getUpdates request; make sure that only one bot instance is running
No error handlers are registered, logging exception.
Traceback (most recent call last):
  File "/root/.venv/lib/python3.11/site-packages/telegram/ext/_application.py", line 1325, in process_update
    await coroutine
  File "/root/.venv/lib/python3.11/site-packages/telegram/ext/_handlers/conversationhandler.py", line 844, in handle_update
    new_state: object = await handler.handle_update(
                        ^^^^^^^^^^^^^^^^^^^^^^^^^^^^
  File "/root/.venv/lib/python3.11/site-packages/telegram/ext/_handlers/basehandler.py", line 158, in handle_update
    return await self.callback(update, context)
           ^^^^^^^^^^^^^^^^^^^^^^^^^^^^^^^^^^^^
  File "/app/12-vfd/backend/server.py", line 635, in cmd_start
    await update.message.reply_text(
  File "/root/.venv/lib/python3.11/site-packages/telegram/_message.py", line 1771, in reply_text
    return await self.get_bot().send_message(
           ^^^^^^^^^^^^^^^^^^^^^^^^^^^^^^^^^^
  File "/root/.venv/lib/python3.11/site-packages/telegram/ext/_extbot.py", line 2965, in send_message
    return await super().send_message(
           ^^^^^^^^^^^^^^^^^^^^^^^^^^^
  File "/root/.venv/lib/python3.11/site-packages/telegram/_bot.py", line 1019, in send_message
    return await self._send_message(
           ^^^^^^^^^^^^^^^^^^^^^^^^^
  File "/root/.venv/lib/python3.11/site-packages/telegram/ext/_extbot.py", line 610, in _send_message
    result = await super()._send_message(
             ^^^^^^^^^^^^^^^^^^^^^^^^^^^^
  File "/root/.venv/lib/python3.11/site-packages/telegram/_bot.py", line 731, in _send_message
    result = await self._post(
             ^^^^^^^^^^^^^^^^^
  File "/root/.venv/lib/python3.11/site-packages/telegram/_bot.py", line 619, in _post
    return await self._do_post(
           ^^^^^^^^^^^^^^^^^^^^
  File "/root/.venv/lib/python3.11/site-packages/telegram/ext/_extbot.py", line 354, in _do_post
    return await super()._do_post(
           ^^^^^^^^^^^^^^^^^^^^^^^
  File "/root/.venv/lib/python3.11/site-packages/telegram/_bot.py", line 648, in _do_post
    result = await request.post(
             ^^^^^^^^^^^^^^^^^^^
  File "/root/.venv/lib/python3.11/site-packages/telegram/request/_baserequest.py", line 202, in post
    result = await self._request_wrapper(
             ^^^^^^^^^^^^^^^^^^^^^^^^^^^^
  File "/root/.venv/lib/python3.11/site-packages/telegram/request/_baserequest.py", line 383, in _request_wrapper
    raise BadRequest(message)
telegram.error.BadRequest: Inline keyboard button web app url 'http://localhost:3000/webapp?user_id=d20d8497315c46e0a9675579e5028818' is invalid: only https links are allowed
Exception happened while polling for updates.
Traceback (most recent call last):
  File "/root/.venv/lib/python3.11/site-packages/telegram/ext/_updater.py", line 750, in _network_loop_retry
    if not await do_action():
           ^^^^^^^^^^^^^^^^^
  File "/root/.venv/lib/python3.11/site-packages/telegram/ext/_updater.py", line 744, in do_action
    return action_cb_task.result()
           ^^^^^^^^^^^^^^^^^^^^^^^
  File "/root/.venv/lib/python3.11/site-packages/telegram/ext/_updater.py", line 371, in polling_action_cb
    updates = await self.bot.get_updates(
              ^^^^^^^^^^^^^^^^^^^^^^^^^^^
  File "/root/.venv/lib/python3.11/site-packages/telegram/ext/_extbot.py", line 650, in get_updates
    updates = await super().get_updates(
              ^^^^^^^^^^^^^^^^^^^^^^^^^^
  File "/root/.venv/lib/python3.11/site-packages/telegram/_bot.py", line 4480, in get_updates
    await self._post(
  File "/root/.venv/lib/python3.11/site-packages/telegram/_bot.py", line 619, in _post
    return await self._do_post(
           ^^^^^^^^^^^^^^^^^^^^
  File "/root/.venv/lib/python3.11/site-packages/telegram/ext/_extbot.py", line 354, in _do_post
    return await super()._do_post(
           ^^^^^^^^^^^^^^^^^^^^^^^
  File "/root/.venv/lib/python3.11/site-packages/telegram/_bot.py", line 648, in _do_post
    result = await request.post(
             ^^^^^^^^^^^^^^^^^^^
  File "/root/.venv/lib/python3.11/site-packages/telegram/request/_baserequest.py", line 202, in post
    result = await self._request_wrapper(
             ^^^^^^^^^^^^^^^^^^^^^^^^^^^^
  File "/root/.venv/lib/python3.11/site-packages/telegram/request/_baserequest.py", line 385, in _request_wrapper
    raise Conflict(message)
telegram.error.Conflict: Conflict: terminated by other getUpdates request; make sure that only one bot instance is running
Exception happened while polling for updates.
Traceback (most recent call last):
  File "/root/.venv/lib/python3.11/site-packages/telegram/ext/_updater.py", line 750, in _network_loop_retry
    if not await do_action():
           ^^^^^^^^^^^^^^^^^
  File "/root/.venv/lib/python3.11/site-packages/telegram/ext/_updater.py", line 744, in do_action
    return action_cb_task.result()
           ^^^^^^^^^^^^^^^^^^^^^^^
  File "/root/.venv/lib/python3.11/site-packages/telegram/ext/_updater.py", line 371, in polling_action_cb
    updates = await self.bot.get_updates(
              ^^^^^^^^^^^^^^^^^^^^^^^^^^^
  File "/root/.venv/lib/python3.11/site-packages/telegram/ext/_extbot.py", line 650, in get_updates
    updates = await super().get_updates(
              ^^^^^^^^^^^^^^^^^^^^^^^^^^
  File "/root/.venv/lib/python3.11/site-packages/telegram/_bot.py", line 4480, in get_updates
    await self._post(
  File "/root/.venv/lib/python3.11/site-packages/telegram/_bot.py", line 619, in _post
    return await self._do_post(
           ^^^^^^^^^^^^^^^^^^^^
  File "/root/.venv/lib/python3.11/site-packages/telegram/ext/_extbot.py", line 354, in _do_post
    return await super()._do_post(
           ^^^^^^^^^^^^^^^^^^^^^^^
  File "/root/.venv/lib/python3.11/site-packages/telegram/_bot.py", line 648, in _do_post
    result = await request.post(
             ^^^^^^^^^^^^^^^^^^^
  File "/root/.venv/lib/python3.11/site-packages/telegram/request/_baserequest.py", line 202, in post
    result = await self._request_wrapper(
             ^^^^^^^^^^^^^^^^^^^^^^^^^^^^
  File "/root/.venv/lib/python3.11/site-packages/telegram/request/_baserequest.py", line 385, in _request_wrapper
    raise Conflict(message)
telegram.error.Conflict: Conflict: terminated by other getUpdates request; make sure that only one bot instance is running
Exception happened while polling for updates.
Traceback (most recent call last):
  File "/root/.venv/lib/python3.11/site-packages/telegram/ext/_updater.py", line 750, in _network_loop_retry
    if not await do_action():
           ^^^^^^^^^^^^^^^^^
  File "/root/.venv/lib/python3.11/site-packages/telegram/ext/_updater.py", line 744, in do_action
    return action_cb_task.result()
           ^^^^^^^^^^^^^^^^^^^^^^^
  File "/root/.venv/lib/python3.11/site-packages/telegram/ext/_updater.py", line 371, in polling_action_cb
    updates = await self.bot.get_updates(
              ^^^^^^^^^^^^^^^^^^^^^^^^^^^
  File "/root/.venv/lib/python3.11/site-packages/telegram/ext/_extbot.py", line 650, in get_updates
    updates = await super().get_updates(
              ^^^^^^^^^^^^^^^^^^^^^^^^^^
  File "/root/.venv/lib/python3.11/site-packages/telegram/_bot.py", line 4480, in get_updates
    await self._post(
  File "/root/.venv/lib/python3.11/site-packages/telegram/_bot.py", line 619, in _post
    return await self._do_post(
           ^^^^^^^^^^^^^^^^^^^^
  File "/root/.venv/lib/python3.11/site-packages/telegram/ext/_extbot.py", line 354, in _do_post
    return await super()._do_post(
           ^^^^^^^^^^^^^^^^^^^^^^^
  File "/root/.venv/lib/python3.11/site-packages/telegram/_bot.py", line 648, in _do_post
    result = await request.post(
             ^^^^^^^^^^^^^^^^^^^
  File "/root/.venv/lib/python3.11/site-packages/telegram/request/_baserequest.py", line 202, in post
    result = await self._request_wrapper(
             ^^^^^^^^^^^^^^^^^^^^^^^^^^^^
  File "/root/.venv/lib/python3.11/site-packages/telegram/request/_baserequest.py", line 385, in _request_wrapper
    raise Conflict(message)
telegram.error.Conflict: Conflict: terminated by other getUpdates request; make sure that only one bot instance is running
Exception happened while polling for updates.
Traceback (most recent call last):
  File "/root/.venv/lib/python3.11/site-packages/telegram/ext/_updater.py", line 750, in _network_loop_retry
    if not await do_action():
           ^^^^^^^^^^^^^^^^^
  File "/root/.venv/lib/python3.11/site-packages/telegram/ext/_updater.py", line 744, in do_action
    return action_cb_task.result()
           ^^^^^^^^^^^^^^^^^^^^^^^
  File "/root/.venv/lib/python3.11/site-packages/telegram/ext/_updater.py", line 371, in polling_action_cb
    updates = await self.bot.get_updates(
              ^^^^^^^^^^^^^^^^^^^^^^^^^^^
  File "/root/.venv/lib/python3.11/site-packages/telegram/ext/_extbot.py", line 650, in get_updates
    updates = await super().get_updates(
              ^^^^^^^^^^^^^^^^^^^^^^^^^^
  File "/root/.venv/lib/python3.11/site-packages/telegram/_bot.py", line 4480, in get_updates
    await self._post(
  File "/root/.venv/lib/python3.11/site-packages/telegram/_bot.py", line 619, in _post
    return await self._do_post(
           ^^^^^^^^^^^^^^^^^^^^
  File "/root/.venv/lib/python3.11/site-packages/telegram/ext/_extbot.py", line 354, in _do_post
    return await super()._do_post(
           ^^^^^^^^^^^^^^^^^^^^^^^
  File "/root/.venv/lib/python3.11/site-packages/telegram/_bot.py", line 648, in _do_post
    result = await request.post(
             ^^^^^^^^^^^^^^^^^^^
  File "/root/.venv/lib/python3.11/site-packages/telegram/request/_baserequest.py", line 202, in post
    result = await self._request_wrapper(
             ^^^^^^^^^^^^^^^^^^^^^^^^^^^^
  File "/root/.venv/lib/python3.11/site-packages/telegram/request/_baserequest.py", line 385, in _request_wrapper
    raise Conflict(message)
telegram.error.Conflict: Conflict: terminated by other getUpdates request; make sure that only one bot instance is running
Exception happened while polling for updates.
Traceback (most recent call last):
  File "/root/.venv/lib/python3.11/site-packages/telegram/ext/_updater.py", line 750, in _network_loop_retry
    if not await do_action():
           ^^^^^^^^^^^^^^^^^
  File "/root/.venv/lib/python3.11/site-packages/telegram/ext/_updater.py", line 744, in do_action
    return action_cb_task.result()
           ^^^^^^^^^^^^^^^^^^^^^^^
  File "/root/.venv/lib/python3.11/site-packages/telegram/ext/_updater.py", line 371, in polling_action_cb
    updates = await self.bot.get_updates(
              ^^^^^^^^^^^^^^^^^^^^^^^^^^^
  File "/root/.venv/lib/python3.11/site-packages/telegram/ext/_extbot.py", line 650, in get_updates
    updates = await super().get_updates(
              ^^^^^^^^^^^^^^^^^^^^^^^^^^
  File "/root/.venv/lib/python3.11/site-packages/telegram/_bot.py", line 4480, in get_updates
    await self._post(
  File "/root/.venv/lib/python3.11/site-packages/telegram/_bot.py", line 619, in _post
    return await self._do_post(
           ^^^^^^^^^^^^^^^^^^^^
  File "/root/.venv/lib/python3.11/site-packages/telegram/ext/_extbot.py", line 354, in _do_post
    return await super()._do_post(
           ^^^^^^^^^^^^^^^^^^^^^^^
  File "/root/.venv/lib/python3.11/site-packages/telegram/_bot.py", line 648, in _do_post
    result = await request.post(
             ^^^^^^^^^^^^^^^^^^^
  File "/root/.venv/lib/python3.11/site-packages/telegram/request/_baserequest.py", line 202, in post
    result = await self._request_wrapper(
             ^^^^^^^^^^^^^^^^^^^^^^^^^^^^
  File "/root/.venv/lib/python3.11/site-packages/telegram/request/_baserequest.py", line 385, in _request_wrapper
    raise Conflict(message)
telegram.error.Conflict: Conflict: terminated by other getUpdates request; make sure that only one bot instance is running
Exception happened while polling for updates.
Traceback (most recent call last):
  File "/root/.venv/lib/python3.11/site-packages/telegram/ext/_updater.py", line 750, in _network_loop_retry
    if not await do_action():
           ^^^^^^^^^^^^^^^^^
  File "/root/.venv/lib/python3.11/site-packages/telegram/ext/_updater.py", line 744, in do_action
    return action_cb_task.result()
           ^^^^^^^^^^^^^^^^^^^^^^^
  File "/root/.venv/lib/python3.11/site-packages/telegram/ext/_updater.py", line 371, in polling_action_cb
    updates = await self.bot.get_updates(
              ^^^^^^^^^^^^^^^^^^^^^^^^^^^
  File "/root/.venv/lib/python3.11/site-packages/telegram/ext/_extbot.py", line 650, in get_updates
    updates = await super().get_updates(
              ^^^^^^^^^^^^^^^^^^^^^^^^^^
  File "/root/.venv/lib/python3.11/site-packages/telegram/_bot.py", line 4480, in get_updates
    await self._post(
  File "/root/.venv/lib/python3.11/site-packages/telegram/_bot.py", line 619, in _post
    return await self._do_post(
           ^^^^^^^^^^^^^^^^^^^^
  File "/root/.venv/lib/python3.11/site-packages/telegram/ext/_extbot.py", line 354, in _do_post
    return await super()._do_post(
           ^^^^^^^^^^^^^^^^^^^^^^^
  File "/root/.venv/lib/python3.11/site-packages/telegram/_bot.py", line 648, in _do_post
    result = await request.post(
             ^^^^^^^^^^^^^^^^^^^
  File "/root/.venv/lib/python3.11/site-packages/telegram/request/_baserequest.py", line 202, in post
    result = await self._request_wrapper(
             ^^^^^^^^^^^^^^^^^^^^^^^^^^^^
  File "/root/.venv/lib/python3.11/site-packages/telegram/request/_baserequest.py", line 385, in _request_wrapper
    raise Conflict(message)
telegram.error.Conflict: Conflict: terminated by other getUpdates request; make sure that only one bot instance is running
Exception happened while polling for updates.
Traceback (most recent call last):
  File "/root/.venv/lib/python3.11/site-packages/telegram/ext/_updater.py", line 750, in _network_loop_retry
    if not await do_action():
           ^^^^^^^^^^^^^^^^^
  File "/root/.venv/lib/python3.11/site-packages/telegram/ext/_updater.py", line 744, in do_action
    return action_cb_task.result()
           ^^^^^^^^^^^^^^^^^^^^^^^
  File "/root/.venv/lib/python3.11/site-packages/telegram/ext/_updater.py", line 371, in polling_action_cb
    updates = await self.bot.get_updates(
              ^^^^^^^^^^^^^^^^^^^^^^^^^^^
  File "/root/.venv/lib/python3.11/site-packages/telegram/ext/_extbot.py", line 650, in get_updates
    updates = await super().get_updates(
              ^^^^^^^^^^^^^^^^^^^^^^^^^^
  File "/root/.venv/lib/python3.11/site-packages/telegram/_bot.py", line 4480, in get_updates
    await self._post(
  File "/root/.venv/lib/python3.11/site-packages/telegram/_bot.py", line 619, in _post
    return await self._do_post(
           ^^^^^^^^^^^^^^^^^^^^
  File "/root/.venv/lib/python3.11/site-packages/telegram/ext/_extbot.py", line 354, in _do_post
    return await super()._do_post(
           ^^^^^^^^^^^^^^^^^^^^^^^
  File "/root/.venv/lib/python3.11/site-packages/telegram/_bot.py", line 648, in _do_post
    result = await request.post(
             ^^^^^^^^^^^^^^^^^^^
  File "/root/.venv/lib/python3.11/site-packages/telegram/request/_baserequest.py", line 202, in post
    result = await self._request_wrapper(
             ^^^^^^^^^^^^^^^^^^^^^^^^^^^^
  File "/root/.venv/lib/python3.11/site-packages/telegram/request/_baserequest.py", line 385, in _request_wrapper
    raise Conflict(message)
telegram.error.Conflict: Conflict: terminated by other getUpdates request; make sure that only one bot instance is running
Exception happened while polling for updates.
Traceback (most recent call last):
  File "/root/.venv/lib/python3.11/site-packages/telegram/ext/_updater.py", line 750, in _network_loop_retry
    if not await do_action():
           ^^^^^^^^^^^^^^^^^
  File "/root/.venv/lib/python3.11/site-packages/telegram/ext/_updater.py", line 744, in do_action
    return action_cb_task.result()
           ^^^^^^^^^^^^^^^^^^^^^^^
  File "/root/.venv/lib/python3.11/site-packages/telegram/ext/_updater.py", line 371, in polling_action_cb
    updates = await self.bot.get_updates(
              ^^^^^^^^^^^^^^^^^^^^^^^^^^^
  File "/root/.venv/lib/python3.11/site-packages/telegram/ext/_extbot.py", line 650, in get_updates
    updates = await super().get_updates(
              ^^^^^^^^^^^^^^^^^^^^^^^^^^
  File "/root/.venv/lib/python3.11/site-packages/telegram/_bot.py", line 4480, in get_updates
    await self._post(
  File "/root/.venv/lib/python3.11/site-packages/telegram/_bot.py", line 619, in _post
    return await self._do_post(
           ^^^^^^^^^^^^^^^^^^^^
  File "/root/.venv/lib/python3.11/site-packages/telegram/ext/_extbot.py", line 354, in _do_post
    return await super()._do_post(
           ^^^^^^^^^^^^^^^^^^^^^^^
  File "/root/.venv/lib/python3.11/site-packages/telegram/_bot.py", line 648, in _do_post
    result = await request.post(
             ^^^^^^^^^^^^^^^^^^^
  File "/root/.venv/lib/python3.11/site-packages/telegram/request/_baserequest.py", line 202, in post
    result = await self._request_wrapper(
             ^^^^^^^^^^^^^^^^^^^^^^^^^^^^
  File "/root/.venv/lib/python3.11/site-packages/telegram/request/_baserequest.py", line 385, in _request_wrapper
    raise Conflict(message)
telegram.error.Conflict: Conflict: terminated by other getUpdates request; make sure that only one bot instance is running
Exception happened while polling for updates.
Traceback (most recent call last):
  File "/root/.venv/lib/python3.11/site-packages/telegram/ext/_updater.py", line 750, in _network_loop_retry
    if not await do_action():
           ^^^^^^^^^^^^^^^^^
  File "/root/.venv/lib/python3.11/site-packages/telegram/ext/_updater.py", line 744, in do_action
    return action_cb_task.result()
           ^^^^^^^^^^^^^^^^^^^^^^^
  File "/root/.venv/lib/python3.11/site-packages/telegram/ext/_updater.py", line 371, in polling_action_cb
    updates = await self.bot.get_updates(
              ^^^^^^^^^^^^^^^^^^^^^^^^^^^
  File "/root/.venv/lib/python3.11/site-packages/telegram/ext/_extbot.py", line 650, in get_updates
    updates = await super().get_updates(
              ^^^^^^^^^^^^^^^^^^^^^^^^^^
  File "/root/.venv/lib/python3.11/site-packages/telegram/_bot.py", line 4480, in get_updates
    await self._post(
  File "/root/.venv/lib/python3.11/site-packages/telegram/_bot.py", line 619, in _post
    return await self._do_post(
           ^^^^^^^^^^^^^^^^^^^^
  File "/root/.venv/lib/python3.11/site-packages/telegram/ext/_extbot.py", line 354, in _do_post
    return await super()._do_post(
           ^^^^^^^^^^^^^^^^^^^^^^^
  File "/root/.venv/lib/python3.11/site-packages/telegram/_bot.py", line 648, in _do_post
    result = await request.post(
             ^^^^^^^^^^^^^^^^^^^
  File "/root/.venv/lib/python3.11/site-packages/telegram/request/_baserequest.py", line 202, in post
    result = await self._request_wrapper(
             ^^^^^^^^^^^^^^^^^^^^^^^^^^^^
  File "/root/.venv/lib/python3.11/site-packages/telegram/request/_baserequest.py", line 385, in _request_wrapper
    raise Conflict(message)
telegram.error.Conflict: Conflict: terminated by other getUpdates request; make sure that only one bot instance is running
Exception happened while polling for updates.
Traceback (most recent call last):
  File "/root/.venv/lib/python3.11/site-packages/telegram/ext/_updater.py", line 750, in _network_loop_retry
    if not await do_action():
           ^^^^^^^^^^^^^^^^^
  File "/root/.venv/lib/python3.11/site-packages/telegram/ext/_updater.py", line 744, in do_action
    return action_cb_task.result()
           ^^^^^^^^^^^^^^^^^^^^^^^
  File "/root/.venv/lib/python3.11/site-packages/telegram/ext/_updater.py", line 371, in polling_action_cb
    updates = await self.bot.get_updates(
              ^^^^^^^^^^^^^^^^^^^^^^^^^^^
  File "/root/.venv/lib/python3.11/site-packages/telegram/ext/_extbot.py", line 650, in get_updates
    updates = await super().get_updates(
              ^^^^^^^^^^^^^^^^^^^^^^^^^^
  File "/root/.venv/lib/python3.11/site-packages/telegram/_bot.py", line 4480, in get_updates
    await self._post(
  File "/root/.venv/lib/python3.11/site-packages/telegram/_bot.py", line 619, in _post
    return await self._do_post(
           ^^^^^^^^^^^^^^^^^^^^
  File "/root/.venv/lib/python3.11/site-packages/telegram/ext/_extbot.py", line 354, in _do_post
    return await super()._do_post(
           ^^^^^^^^^^^^^^^^^^^^^^^
  File "/root/.venv/lib/python3.11/site-packages/telegram/_bot.py", line 648, in _do_post
    result = await request.post(
             ^^^^^^^^^^^^^^^^^^^
  File "/root/.venv/lib/python3.11/site-packages/telegram/request/_baserequest.py", line 202, in post
    result = await self._request_wrapper(
             ^^^^^^^^^^^^^^^^^^^^^^^^^^^^
  File "/root/.venv/lib/python3.11/site-packages/telegram/request/_baserequest.py", line 385, in _request_wrapper
    raise Conflict(message)
telegram.error.Conflict: Conflict: terminated by other getUpdates request; make sure that only one bot instance is running
Exception happened while polling for updates.
Traceback (most recent call last):
  File "/root/.venv/lib/python3.11/site-packages/telegram/ext/_updater.py", line 750, in _network_loop_retry
    if not await do_action():
           ^^^^^^^^^^^^^^^^^
  File "/root/.venv/lib/python3.11/site-packages/telegram/ext/_updater.py", line 744, in do_action
    return action_cb_task.result()
           ^^^^^^^^^^^^^^^^^^^^^^^
  File "/root/.venv/lib/python3.11/site-packages/telegram/ext/_updater.py", line 371, in polling_action_cb
    updates = await self.bot.get_updates(
              ^^^^^^^^^^^^^^^^^^^^^^^^^^^
  File "/root/.venv/lib/python3.11/site-packages/telegram/ext/_extbot.py", line 650, in get_updates
    updates = await super().get_updates(
              ^^^^^^^^^^^^^^^^^^^^^^^^^^
  File "/root/.venv/lib/python3.11/site-packages/telegram/_bot.py", line 4480, in get_updates
    await self._post(
  File "/root/.venv/lib/python3.11/site-packages/telegram/_bot.py", line 619, in _post
    return await self._do_post(
           ^^^^^^^^^^^^^^^^^^^^
  File "/root/.venv/lib/python3.11/site-packages/telegram/ext/_extbot.py", line 354, in _do_post
    return await super()._do_post(
           ^^^^^^^^^^^^^^^^^^^^^^^
  File "/root/.venv/lib/python3.11/site-packages/telegram/_bot.py", line 648, in _do_post
    result = await request.post(
             ^^^^^^^^^^^^^^^^^^^
  File "/root/.venv/lib/python3.11/site-packages/telegram/request/_baserequest.py", line 202, in post
    result = await self._request_wrapper(
             ^^^^^^^^^^^^^^^^^^^^^^^^^^^^
  File "/root/.venv/lib/python3.11/site-packages/telegram/request/_baserequest.py", line 385, in _request_wrapper
    raise Conflict(message)
telegram.error.Conflict: Conflict: terminated by other getUpdates request; make sure that only one bot instance is running
Exception happened while polling for updates.
Traceback (most recent call last):
  File "/root/.venv/lib/python3.11/site-packages/telegram/ext/_updater.py", line 750, in _network_loop_retry
    if not await do_action():
           ^^^^^^^^^^^^^^^^^
  File "/root/.venv/lib/python3.11/site-packages/telegram/ext/_updater.py", line 744, in do_action
    return action_cb_task.result()
           ^^^^^^^^^^^^^^^^^^^^^^^
  File "/root/.venv/lib/python3.11/site-packages/telegram/ext/_updater.py", line 371, in polling_action_cb
    updates = await self.bot.get_updates(
              ^^^^^^^^^^^^^^^^^^^^^^^^^^^
  File "/root/.venv/lib/python3.11/site-packages/telegram/ext/_extbot.py", line 650, in get_updates
    updates = await super().get_updates(
              ^^^^^^^^^^^^^^^^^^^^^^^^^^
  File "/root/.venv/lib/python3.11/site-packages/telegram/_bot.py", line 4480, in get_updates
    await self._post(
  File "/root/.venv/lib/python3.11/site-packages/telegram/_bot.py", line 619, in _post
    return await self._do_post(
           ^^^^^^^^^^^^^^^^^^^^
  File "/root/.venv/lib/python3.11/site-packages/telegram/ext/_extbot.py", line 354, in _do_post
    return await super()._do_post(
           ^^^^^^^^^^^^^^^^^^^^^^^
  File "/root/.venv/lib/python3.11/site-packages/telegram/_bot.py", line 648, in _do_post
    result = await request.post(
             ^^^^^^^^^^^^^^^^^^^
  File "/root/.venv/lib/python3.11/site-packages/telegram/request/_baserequest.py", line 202, in post
    result = await self._request_wrapper(
             ^^^^^^^^^^^^^^^^^^^^^^^^^^^^
  File "/root/.venv/lib/python3.11/site-packages/telegram/request/_baserequest.py", line 385, in _request_wrapper
    raise Conflict(message)
telegram.error.Conflict: Conflict: terminated by other getUpdates request; make sure that only one bot instance is running
Exception happened while polling for updates.
Traceback (most recent call last):
  File "/root/.venv/lib/python3.11/site-packages/telegram/ext/_updater.py", line 750, in _network_loop_retry
    if not await do_action():
           ^^^^^^^^^^^^^^^^^
  File "/root/.venv/lib/python3.11/site-packages/telegram/ext/_updater.py", line 744, in do_action
    return action_cb_task.result()
           ^^^^^^^^^^^^^^^^^^^^^^^
  File "/root/.venv/lib/python3.11/site-packages/telegram/ext/_updater.py", line 371, in polling_action_cb
    updates = await self.bot.get_updates(
              ^^^^^^^^^^^^^^^^^^^^^^^^^^^
  File "/root/.venv/lib/python3.11/site-packages/telegram/ext/_extbot.py", line 650, in get_updates
    updates = await super().get_updates(
              ^^^^^^^^^^^^^^^^^^^^^^^^^^
  File "/root/.venv/lib/python3.11/site-packages/telegram/_bot.py", line 4480, in get_updates
    await self._post(
  File "/root/.venv/lib/python3.11/site-packages/telegram/_bot.py", line 619, in _post
    return await self._do_post(
           ^^^^^^^^^^^^^^^^^^^^
  File "/root/.venv/lib/python3.11/site-packages/telegram/ext/_extbot.py", line 354, in _do_post
    return await super()._do_post(
           ^^^^^^^^^^^^^^^^^^^^^^^
  File "/root/.venv/lib/python3.11/site-packages/telegram/_bot.py", line 648, in _do_post
    result = await request.post(
             ^^^^^^^^^^^^^^^^^^^
  File "/root/.venv/lib/python3.11/site-packages/telegram/request/_baserequest.py", line 202, in post
    result = await self._request_wrapper(
             ^^^^^^^^^^^^^^^^^^^^^^^^^^^^
  File "/root/.venv/lib/python3.11/site-packages/telegram/request/_baserequest.py", line 385, in _request_wrapper
    raise Conflict(message)
telegram.error.Conflict: Conflict: terminated by other getUpdates request; make sure that only one bot instance is running
Exception happened while polling for updates.
Traceback (most recent call last):
  File "/root/.venv/lib/python3.11/site-packages/telegram/ext/_updater.py", line 750, in _network_loop_retry
    if not await do_action():
           ^^^^^^^^^^^^^^^^^
  File "/root/.venv/lib/python3.11/site-packages/telegram/ext/_updater.py", line 744, in do_action
    return action_cb_task.result()
           ^^^^^^^^^^^^^^^^^^^^^^^
  File "/root/.venv/lib/python3.11/site-packages/telegram/ext/_updater.py", line 371, in polling_action_cb
    updates = await self.bot.get_updates(
              ^^^^^^^^^^^^^^^^^^^^^^^^^^^
  File "/root/.venv/lib/python3.11/site-packages/telegram/ext/_extbot.py", line 650, in get_updates
    updates = await super().get_updates(
              ^^^^^^^^^^^^^^^^^^^^^^^^^^
  File "/root/.venv/lib/python3.11/site-packages/telegram/_bot.py", line 4480, in get_updates
    await self._post(
  File "/root/.venv/lib/python3.11/site-packages/telegram/_bot.py", line 619, in _post
    return await self._do_post(
           ^^^^^^^^^^^^^^^^^^^^
  File "/root/.venv/lib/python3.11/site-packages/telegram/ext/_extbot.py", line 354, in _do_post
    return await super()._do_post(
           ^^^^^^^^^^^^^^^^^^^^^^^
  File "/root/.venv/lib/python3.11/site-packages/telegram/_bot.py", line 648, in _do_post
    result = await request.post(
             ^^^^^^^^^^^^^^^^^^^
  File "/root/.venv/lib/python3.11/site-packages/telegram/request/_baserequest.py", line 202, in post
    result = await self._request_wrapper(
             ^^^^^^^^^^^^^^^^^^^^^^^^^^^^
  File "/root/.venv/lib/python3.11/site-packages/telegram/request/_baserequest.py", line 385, in _request_wrapper
    raise Conflict(message)
telegram.error.Conflict: Conflict: terminated by other getUpdates request; make sure that only one bot instance is running
Exception happened while polling for updates.
Traceback (most recent call last):
  File "/root/.venv/lib/python3.11/site-packages/telegram/ext/_updater.py", line 750, in _network_loop_retry
    if not await do_action():
           ^^^^^^^^^^^^^^^^^
  File "/root/.venv/lib/python3.11/site-packages/telegram/ext/_updater.py", line 744, in do_action
    return action_cb_task.result()
           ^^^^^^^^^^^^^^^^^^^^^^^
  File "/root/.venv/lib/python3.11/site-packages/telegram/ext/_updater.py", line 371, in polling_action_cb
    updates = await self.bot.get_updates(
              ^^^^^^^^^^^^^^^^^^^^^^^^^^^
  File "/root/.venv/lib/python3.11/site-packages/telegram/ext/_extbot.py", line 650, in get_updates
    updates = await super().get_updates(
              ^^^^^^^^^^^^^^^^^^^^^^^^^^
  File "/root/.venv/lib/python3.11/site-packages/telegram/_bot.py", line 4480, in get_updates
    await self._post(
  File "/root/.venv/lib/python3.11/site-packages/telegram/_bot.py", line 619, in _post
    return await self._do_post(
           ^^^^^^^^^^^^^^^^^^^^
  File "/root/.venv/lib/python3.11/site-packages/telegram/ext/_extbot.py", line 354, in _do_post
    return await super()._do_post(
           ^^^^^^^^^^^^^^^^^^^^^^^
  File "/root/.venv/lib/python3.11/site-packages/telegram/_bot.py", line 648, in _do_post
    result = await request.post(
             ^^^^^^^^^^^^^^^^^^^
  File "/root/.venv/lib/python3.11/site-packages/telegram/request/_baserequest.py", line 202, in post
    result = await self._request_wrapper(
             ^^^^^^^^^^^^^^^^^^^^^^^^^^^^
  File "/root/.venv/lib/python3.11/site-packages/telegram/request/_baserequest.py", line 385, in _request_wrapper
    raise Conflict(message)
telegram.error.Conflict: Conflict: terminated by other getUpdates request; make sure that only one bot instance is running
Exception happened while polling for updates.
Traceback (most recent call last):
  File "/root/.venv/lib/python3.11/site-packages/telegram/ext/_updater.py", line 750, in _network_loop_retry
    if not await do_action():
           ^^^^^^^^^^^^^^^^^
  File "/root/.venv/lib/python3.11/site-packages/telegram/ext/_updater.py", line 744, in do_action
    return action_cb_task.result()
           ^^^^^^^^^^^^^^^^^^^^^^^
  File "/root/.venv/lib/python3.11/site-packages/telegram/ext/_updater.py", line 371, in polling_action_cb
    updates = await self.bot.get_updates(
              ^^^^^^^^^^^^^^^^^^^^^^^^^^^
  File "/root/.venv/lib/python3.11/site-packages/telegram/ext/_extbot.py", line 650, in get_updates
    updates = await super().get_updates(
              ^^^^^^^^^^^^^^^^^^^^^^^^^^
  File "/root/.venv/lib/python3.11/site-packages/telegram/_bot.py", line 4480, in get_updates
    await self._post(
  File "/root/.venv/lib/python3.11/site-packages/telegram/_bot.py", line 619, in _post
    return await self._do_post(
           ^^^^^^^^^^^^^^^^^^^^
  File "/root/.venv/lib/python3.11/site-packages/telegram/ext/_extbot.py", line 354, in _do_post
    return await super()._do_post(
           ^^^^^^^^^^^^^^^^^^^^^^^
  File "/root/.venv/lib/python3.11/site-packages/telegram/_bot.py", line 648, in _do_post
    result = await request.post(
             ^^^^^^^^^^^^^^^^^^^
  File "/root/.venv/lib/python3.11/site-packages/telegram/request/_baserequest.py", line 202, in post
    result = await self._request_wrapper(
             ^^^^^^^^^^^^^^^^^^^^^^^^^^^^
  File "/root/.venv/lib/python3.11/site-packages/telegram/request/_baserequest.py", line 385, in _request_wrapper
    raise Conflict(message)
telegram.error.Conflict: Conflict: terminated by other getUpdates request; make sure that only one bot instance is running
Exception happened while polling for updates.
Traceback (most recent call last):
  File "/root/.venv/lib/python3.11/site-packages/telegram/ext/_updater.py", line 750, in _network_loop_retry
    if not await do_action():
           ^^^^^^^^^^^^^^^^^
  File "/root/.venv/lib/python3.11/site-packages/telegram/ext/_updater.py", line 744, in do_action
    return action_cb_task.result()
           ^^^^^^^^^^^^^^^^^^^^^^^
  File "/root/.venv/lib/python3.11/site-packages/telegram/ext/_updater.py", line 371, in polling_action_cb
    updates = await self.bot.get_updates(
              ^^^^^^^^^^^^^^^^^^^^^^^^^^^
  File "/root/.venv/lib/python3.11/site-packages/telegram/ext/_extbot.py", line 650, in get_updates
    updates = await super().get_updates(
              ^^^^^^^^^^^^^^^^^^^^^^^^^^
  File "/root/.venv/lib/python3.11/site-packages/telegram/_bot.py", line 4480, in get_updates
    await self._post(
  File "/root/.venv/lib/python3.11/site-packages/telegram/_bot.py", line 619, in _post
    return await self._do_post(
           ^^^^^^^^^^^^^^^^^^^^
  File "/root/.venv/lib/python3.11/site-packages/telegram/ext/_extbot.py", line 354, in _do_post
    return await super()._do_post(
           ^^^^^^^^^^^^^^^^^^^^^^^
  File "/root/.venv/lib/python3.11/site-packages/telegram/_bot.py", line 648, in _do_post
    result = await request.post(
             ^^^^^^^^^^^^^^^^^^^
  File "/root/.venv/lib/python3.11/site-packages/telegram/request/_baserequest.py", line 202, in post
    result = await self._request_wrapper(
             ^^^^^^^^^^^^^^^^^^^^^^^^^^^^
  File "/root/.venv/lib/python3.11/site-packages/telegram/request/_baserequest.py", line 385, in _request_wrapper
    raise Conflict(message)
telegram.error.Conflict: Conflict: terminated by other getUpdates request; make sure that only one bot instance is running
Exception happened while polling for updates.
Traceback (most recent call last):
  File "/root/.venv/lib/python3.11/site-packages/telegram/ext/_updater.py", line 750, in _network_loop_retry
    if not await do_action():
           ^^^^^^^^^^^^^^^^^
  File "/root/.venv/lib/python3.11/site-packages/telegram/ext/_updater.py", line 744, in do_action
    return action_cb_task.result()
           ^^^^^^^^^^^^^^^^^^^^^^^
  File "/root/.venv/lib/python3.11/site-packages/telegram/ext/_updater.py", line 371, in polling_action_cb
    updates = await self.bot.get_updates(
              ^^^^^^^^^^^^^^^^^^^^^^^^^^^
  File "/root/.venv/lib/python3.11/site-packages/telegram/ext/_extbot.py", line 650, in get_updates
    updates = await super().get_updates(
              ^^^^^^^^^^^^^^^^^^^^^^^^^^
  File "/root/.venv/lib/python3.11/site-packages/telegram/_bot.py", line 4480, in get_updates
    await self._post(
  File "/root/.venv/lib/python3.11/site-packages/telegram/_bot.py", line 619, in _post
    return await self._do_post(
           ^^^^^^^^^^^^^^^^^^^^
  File "/root/.venv/lib/python3.11/site-packages/telegram/ext/_extbot.py", line 354, in _do_post
    return await super()._do_post(
           ^^^^^^^^^^^^^^^^^^^^^^^
  File "/root/.venv/lib/python3.11/site-packages/telegram/_bot.py", line 648, in _do_post
    result = await request.post(
             ^^^^^^^^^^^^^^^^^^^
  File "/root/.venv/lib/python3.11/site-packages/telegram/request/_baserequest.py", line 202, in post
    result = await self._request_wrapper(
             ^^^^^^^^^^^^^^^^^^^^^^^^^^^^
  File "/root/.venv/lib/python3.11/site-packages/telegram/request/_baserequest.py", line 385, in _request_wrapper
    raise Conflict(message)
telegram.error.Conflict: Conflict: terminated by other getUpdates request; make sure that only one bot instance is running
Exception happened while polling for updates.
Traceback (most recent call last):
  File "/root/.venv/lib/python3.11/site-packages/telegram/ext/_updater.py", line 750, in _network_loop_retry
    if not await do_action():
           ^^^^^^^^^^^^^^^^^
  File "/root/.venv/lib/python3.11/site-packages/telegram/ext/_updater.py", line 744, in do_action
    return action_cb_task.result()
           ^^^^^^^^^^^^^^^^^^^^^^^
  File "/root/.venv/lib/python3.11/site-packages/telegram/ext/_updater.py", line 371, in polling_action_cb
    updates = await self.bot.get_updates(
              ^^^^^^^^^^^^^^^^^^^^^^^^^^^
  File "/root/.venv/lib/python3.11/site-packages/telegram/ext/_extbot.py", line 650, in get_updates
    updates = await super().get_updates(
              ^^^^^^^^^^^^^^^^^^^^^^^^^^
  File "/root/.venv/lib/python3.11/site-packages/telegram/_bot.py", line 4480, in get_updates
    await self._post(
  File "/root/.venv/lib/python3.11/site-packages/telegram/_bot.py", line 619, in _post
    return await self._do_post(
           ^^^^^^^^^^^^^^^^^^^^
  File "/root/.venv/lib/python3.11/site-packages/telegram/ext/_extbot.py", line 354, in _do_post
    return await super()._do_post(
           ^^^^^^^^^^^^^^^^^^^^^^^
  File "/root/.venv/lib/python3.11/site-packages/telegram/_bot.py", line 648, in _do_post
    result = await request.post(
             ^^^^^^^^^^^^^^^^^^^
  File "/root/.venv/lib/python3.11/site-packages/telegram/request/_baserequest.py", line 202, in post
    result = await self._request_wrapper(
             ^^^^^^^^^^^^^^^^^^^^^^^^^^^^
  File "/root/.venv/lib/python3.11/site-packages/telegram/request/_baserequest.py", line 385, in _request_wrapper
    raise Conflict(message)
telegram.error.Conflict: Conflict: terminated by other getUpdates request; make sure that only one bot instance is running
Exception happened while polling for updates.
Traceback (most recent call last):
  File "/root/.venv/lib/python3.11/site-packages/telegram/ext/_updater.py", line 750, in _network_loop_retry
    if not await do_action():
           ^^^^^^^^^^^^^^^^^
  File "/root/.venv/lib/python3.11/site-packages/telegram/ext/_updater.py", line 744, in do_action
    return action_cb_task.result()
           ^^^^^^^^^^^^^^^^^^^^^^^
  File "/root/.venv/lib/python3.11/site-packages/telegram/ext/_updater.py", line 371, in polling_action_cb
    updates = await self.bot.get_updates(
              ^^^^^^^^^^^^^^^^^^^^^^^^^^^
  File "/root/.venv/lib/python3.11/site-packages/telegram/ext/_extbot.py", line 650, in get_updates
    updates = await super().get_updates(
              ^^^^^^^^^^^^^^^^^^^^^^^^^^
  File "/root/.venv/lib/python3.11/site-packages/telegram/_bot.py", line 4480, in get_updates
    await self._post(
  File "/root/.venv/lib/python3.11/site-packages/telegram/_bot.py", line 619, in _post
    return await self._do_post(
           ^^^^^^^^^^^^^^^^^^^^
  File "/root/.venv/lib/python3.11/site-packages/telegram/ext/_extbot.py", line 354, in _do_post
    return await super()._do_post(
           ^^^^^^^^^^^^^^^^^^^^^^^
  File "/root/.venv/lib/python3.11/site-packages/telegram/_bot.py", line 648, in _do_post
    result = await request.post(
             ^^^^^^^^^^^^^^^^^^^
  File "/root/.venv/lib/python3.11/site-packages/telegram/request/_baserequest.py", line 202, in post
    result = await self._request_wrapper(
             ^^^^^^^^^^^^^^^^^^^^^^^^^^^^
  File "/root/.venv/lib/python3.11/site-packages/telegram/request/_baserequest.py", line 385, in _request_wrapper
    raise Conflict(message)
telegram.error.Conflict: Conflict: terminated by other getUpdates request; make sure that only one bot instance is running
Exception happened while polling for updates.
Traceback (most recent call last):
  File "/root/.venv/lib/python3.11/site-packages/telegram/ext/_updater.py", line 750, in _network_loop_retry
    if not await do_action():
           ^^^^^^^^^^^^^^^^^
  File "/root/.venv/lib/python3.11/site-packages/telegram/ext/_updater.py", line 744, in do_action
    return action_cb_task.result()
           ^^^^^^^^^^^^^^^^^^^^^^^
  File "/root/.venv/lib/python3.11/site-packages/telegram/ext/_updater.py", line 371, in polling_action_cb
    updates = await self.bot.get_updates(
              ^^^^^^^^^^^^^^^^^^^^^^^^^^^
  File "/root/.venv/lib/python3.11/site-packages/telegram/ext/_extbot.py", line 650, in get_updates
    updates = await super().get_updates(
              ^^^^^^^^^^^^^^^^^^^^^^^^^^
  File "/root/.venv/lib/python3.11/site-packages/telegram/_bot.py", line 4480, in get_updates
    await self._post(
  File "/root/.venv/lib/python3.11/site-packages/telegram/_bot.py", line 619, in _post
    return await self._do_post(
           ^^^^^^^^^^^^^^^^^^^^
  File "/root/.venv/lib/python3.11/site-packages/telegram/ext/_extbot.py", line 354, in _do_post
    return await super()._do_post(
           ^^^^^^^^^^^^^^^^^^^^^^^
  File "/root/.venv/lib/python3.11/site-packages/telegram/_bot.py", line 648, in _do_post
    result = await request.post(
             ^^^^^^^^^^^^^^^^^^^
  File "/root/.venv/lib/python3.11/site-packages/telegram/request/_baserequest.py", line 202, in post
    result = await self._request_wrapper(
             ^^^^^^^^^^^^^^^^^^^^^^^^^^^^
  File "/root/.venv/lib/python3.11/site-packages/telegram/request/_baserequest.py", line 385, in _request_wrapper
    raise Conflict(message)
telegram.error.Conflict: Conflict: terminated by other getUpdates request; make sure that only one bot instance is running
Exception happened while polling for updates.
Traceback (most recent call last):
  File "/root/.venv/lib/python3.11/site-packages/telegram/ext/_updater.py", line 750, in _network_loop_retry
    if not await do_action():
           ^^^^^^^^^^^^^^^^^
  File "/root/.venv/lib/python3.11/site-packages/telegram/ext/_updater.py", line 744, in do_action
    return action_cb_task.result()
           ^^^^^^^^^^^^^^^^^^^^^^^
  File "/root/.venv/lib/python3.11/site-packages/telegram/ext/_updater.py", line 371, in polling_action_cb
    updates = await self.bot.get_updates(
              ^^^^^^^^^^^^^^^^^^^^^^^^^^^
  File "/root/.venv/lib/python3.11/site-packages/telegram/ext/_extbot.py", line 650, in get_updates
    updates = await super().get_updates(
              ^^^^^^^^^^^^^^^^^^^^^^^^^^
  File "/root/.venv/lib/python3.11/site-packages/telegram/_bot.py", line 4480, in get_updates
    await self._post(
  File "/root/.venv/lib/python3.11/site-packages/telegram/_bot.py", line 619, in _post
    return await self._do_post(
           ^^^^^^^^^^^^^^^^^^^^
  File "/root/.venv/lib/python3.11/site-packages/telegram/ext/_extbot.py", line 354, in _do_post
    return await super()._do_post(
           ^^^^^^^^^^^^^^^^^^^^^^^
  File "/root/.venv/lib/python3.11/site-packages/telegram/_bot.py", line 648, in _do_post
    result = await request.post(
             ^^^^^^^^^^^^^^^^^^^
  File "/root/.venv/lib/python3.11/site-packages/telegram/request/_baserequest.py", line 202, in post
    result = await self._request_wrapper(
             ^^^^^^^^^^^^^^^^^^^^^^^^^^^^
  File "/root/.venv/lib/python3.11/site-packages/telegram/request/_baserequest.py", line 385, in _request_wrapper
    raise Conflict(message)
telegram.error.Conflict: Conflict: terminated by other getUpdates request; make sure that only one bot instance is running
Exception happened while polling for updates.
Traceback (most recent call last):
  File "/root/.venv/lib/python3.11/site-packages/telegram/ext/_updater.py", line 750, in _network_loop_retry
    if not await do_action():
           ^^^^^^^^^^^^^^^^^
  File "/root/.venv/lib/python3.11/site-packages/telegram/ext/_updater.py", line 744, in do_action
    return action_cb_task.result()
           ^^^^^^^^^^^^^^^^^^^^^^^
  File "/root/.venv/lib/python3.11/site-packages/telegram/ext/_updater.py", line 371, in polling_action_cb
    updates = await self.bot.get_updates(
              ^^^^^^^^^^^^^^^^^^^^^^^^^^^
  File "/root/.venv/lib/python3.11/site-packages/telegram/ext/_extbot.py", line 650, in get_updates
    updates = await super().get_updates(
              ^^^^^^^^^^^^^^^^^^^^^^^^^^
  File "/root/.venv/lib/python3.11/site-packages/telegram/_bot.py", line 4480, in get_updates
    await self._post(
  File "/root/.venv/lib/python3.11/site-packages/telegram/_bot.py", line 619, in _post
    return await self._do_post(
           ^^^^^^^^^^^^^^^^^^^^
  File "/root/.venv/lib/python3.11/site-packages/telegram/ext/_extbot.py", line 354, in _do_post
    return await super()._do_post(
           ^^^^^^^^^^^^^^^^^^^^^^^
  File "/root/.venv/lib/python3.11/site-packages/telegram/_bot.py", line 648, in _do_post
    result = await request.post(
             ^^^^^^^^^^^^^^^^^^^
  File "/root/.venv/lib/python3.11/site-packages/telegram/request/_baserequest.py", line 202, in post
    result = await self._request_wrapper(
             ^^^^^^^^^^^^^^^^^^^^^^^^^^^^
  File "/root/.venv/lib/python3.11/site-packages/telegram/request/_baserequest.py", line 385, in _request_wrapper
    raise Conflict(message)
telegram.error.Conflict: Conflict: terminated by other getUpdates request; make sure that only one bot instance is running
Exception happened while polling for updates.
Traceback (most recent call last):
  File "/root/.venv/lib/python3.11/site-packages/telegram/ext/_updater.py", line 750, in _network_loop_retry
    if not await do_action():
           ^^^^^^^^^^^^^^^^^
  File "/root/.venv/lib/python3.11/site-packages/telegram/ext/_updater.py", line 744, in do_action
    return action_cb_task.result()
           ^^^^^^^^^^^^^^^^^^^^^^^
  File "/root/.venv/lib/python3.11/site-packages/telegram/ext/_updater.py", line 371, in polling_action_cb
    updates = await self.bot.get_updates(
              ^^^^^^^^^^^^^^^^^^^^^^^^^^^
  File "/root/.venv/lib/python3.11/site-packages/telegram/ext/_extbot.py", line 650, in get_updates
    updates = await super().get_updates(
              ^^^^^^^^^^^^^^^^^^^^^^^^^^
  File "/root/.venv/lib/python3.11/site-packages/telegram/_bot.py", line 4480, in get_updates
    await self._post(
  File "/root/.venv/lib/python3.11/site-packages/telegram/_bot.py", line 619, in _post
    return await self._do_post(
           ^^^^^^^^^^^^^^^^^^^^
  File "/root/.venv/lib/python3.11/site-packages/telegram/ext/_extbot.py", line 354, in _do_post
    return await super()._do_post(
           ^^^^^^^^^^^^^^^^^^^^^^^
  File "/root/.venv/lib/python3.11/site-packages/telegram/_bot.py", line 648, in _do_post
    result = await request.post(
             ^^^^^^^^^^^^^^^^^^^
  File "/root/.venv/lib/python3.11/site-packages/telegram/request/_baserequest.py", line 202, in post
    result = await self._request_wrapper(
             ^^^^^^^^^^^^^^^^^^^^^^^^^^^^
  File "/root/.venv/lib/python3.11/site-packages/telegram/request/_baserequest.py", line 385, in _request_wrapper
    raise Conflict(message)
telegram.error.Conflict: Conflict: terminated by other getUpdates request; make sure that only one bot instance is running
Exception happened while polling for updates.
Traceback (most recent call last):
  File "/root/.venv/lib/python3.11/site-packages/telegram/ext/_updater.py", line 750, in _network_loop_retry
    if not await do_action():
           ^^^^^^^^^^^^^^^^^
  File "/root/.venv/lib/python3.11/site-packages/telegram/ext/_updater.py", line 744, in do_action
    return action_cb_task.result()
           ^^^^^^^^^^^^^^^^^^^^^^^
  File "/root/.venv/lib/python3.11/site-packages/telegram/ext/_updater.py", line 371, in polling_action_cb
    updates = await self.bot.get_updates(
              ^^^^^^^^^^^^^^^^^^^^^^^^^^^
  File "/root/.venv/lib/python3.11/site-packages/telegram/ext/_extbot.py", line 650, in get_updates
    updates = await super().get_updates(
              ^^^^^^^^^^^^^^^^^^^^^^^^^^
  File "/root/.venv/lib/python3.11/site-packages/telegram/_bot.py", line 4480, in get_updates
    await self._post(
  File "/root/.venv/lib/python3.11/site-packages/telegram/_bot.py", line 619, in _post
    return await self._do_post(
           ^^^^^^^^^^^^^^^^^^^^
  File "/root/.venv/lib/python3.11/site-packages/telegram/ext/_extbot.py", line 354, in _do_post
    return await super()._do_post(
           ^^^^^^^^^^^^^^^^^^^^^^^
  File "/root/.venv/lib/python3.11/site-packages/telegram/_bot.py", line 648, in _do_post
    result = await request.post(
             ^^^^^^^^^^^^^^^^^^^
  File "/root/.venv/lib/python3.11/site-packages/telegram/request/_baserequest.py", line 202, in post
    result = await self._request_wrapper(
             ^^^^^^^^^^^^^^^^^^^^^^^^^^^^
  File "/root/.venv/lib/python3.11/site-packages/telegram/request/_baserequest.py", line 385, in _request_wrapper
    raise Conflict(message)
telegram.error.Conflict: Conflict: terminated by other getUpdates request; make sure that only one bot instance is running
Exception happened while polling for updates.
Traceback (most recent call last):
  File "/root/.venv/lib/python3.11/site-packages/telegram/ext/_updater.py", line 750, in _network_loop_retry
    if not await do_action():
           ^^^^^^^^^^^^^^^^^
  File "/root/.venv/lib/python3.11/site-packages/telegram/ext/_updater.py", line 744, in do_action
    return action_cb_task.result()
           ^^^^^^^^^^^^^^^^^^^^^^^
  File "/root/.venv/lib/python3.11/site-packages/telegram/ext/_updater.py", line 371, in polling_action_cb
    updates = await self.bot.get_updates(
              ^^^^^^^^^^^^^^^^^^^^^^^^^^^
  File "/root/.venv/lib/python3.11/site-packages/telegram/ext/_extbot.py", line 650, in get_updates
    updates = await super().get_updates(
              ^^^^^^^^^^^^^^^^^^^^^^^^^^
  File "/root/.venv/lib/python3.11/site-packages/telegram/_bot.py", line 4480, in get_updates
    await self._post(
  File "/root/.venv/lib/python3.11/site-packages/telegram/_bot.py", line 619, in _post
    return await self._do_post(
           ^^^^^^^^^^^^^^^^^^^^
  File "/root/.venv/lib/python3.11/site-packages/telegram/ext/_extbot.py", line 354, in _do_post
    return await super()._do_post(
           ^^^^^^^^^^^^^^^^^^^^^^^
  File "/root/.venv/lib/python3.11/site-packages/telegram/_bot.py", line 648, in _do_post
    result = await request.post(
             ^^^^^^^^^^^^^^^^^^^
  File "/root/.venv/lib/python3.11/site-packages/telegram/request/_baserequest.py", line 202, in post
    result = await self._request_wrapper(
             ^^^^^^^^^^^^^^^^^^^^^^^^^^^^
  File "/root/.venv/lib/python3.11/site-packages/telegram/request/_baserequest.py", line 385, in _request_wrapper
    raise Conflict(message)
telegram.error.Conflict: Conflict: terminated by other getUpdates request; make sure that only one bot instance is running
Exception happened while polling for updates.
Traceback (most recent call last):
  File "/root/.venv/lib/python3.11/site-packages/telegram/ext/_updater.py", line 750, in _network_loop_retry
    if not await do_action():
           ^^^^^^^^^^^^^^^^^
  File "/root/.venv/lib/python3.11/site-packages/telegram/ext/_updater.py", line 744, in do_action
    return action_cb_task.result()
           ^^^^^^^^^^^^^^^^^^^^^^^
  File "/root/.venv/lib/python3.11/site-packages/telegram/ext/_updater.py", line 371, in polling_action_cb
    updates = await self.bot.get_updates(
              ^^^^^^^^^^^^^^^^^^^^^^^^^^^
  File "/root/.venv/lib/python3.11/site-packages/telegram/ext/_extbot.py", line 650, in get_updates
    updates = await super().get_updates(
              ^^^^^^^^^^^^^^^^^^^^^^^^^^
  File "/root/.venv/lib/python3.11/site-packages/telegram/_bot.py", line 4480, in get_updates
    await self._post(
  File "/root/.venv/lib/python3.11/site-packages/telegram/_bot.py", line 619, in _post
    return await self._do_post(
           ^^^^^^^^^^^^^^^^^^^^
  File "/root/.venv/lib/python3.11/site-packages/telegram/ext/_extbot.py", line 354, in _do_post
    return await super()._do_post(
           ^^^^^^^^^^^^^^^^^^^^^^^
  File "/root/.venv/lib/python3.11/site-packages/telegram/_bot.py", line 648, in _do_post
    result = await request.post(
             ^^^^^^^^^^^^^^^^^^^
  File "/root/.venv/lib/python3.11/site-packages/telegram/request/_baserequest.py", line 202, in post
    result = await self._request_wrapper(
             ^^^^^^^^^^^^^^^^^^^^^^^^^^^^
  File "/root/.venv/lib/python3.11/site-packages/telegram/request/_baserequest.py", line 385, in _request_wrapper
    raise Conflict(message)
telegram.error.Conflict: Conflict: terminated by other getUpdates request; make sure that only one bot instance is running
Exception happened while polling for updates.
Traceback (most recent call last):
  File "/root/.venv/lib/python3.11/site-packages/telegram/ext/_updater.py", line 750, in _network_loop_retry
    if not await do_action():
           ^^^^^^^^^^^^^^^^^
  File "/root/.venv/lib/python3.11/site-packages/telegram/ext/_updater.py", line 744, in do_action
    return action_cb_task.result()
           ^^^^^^^^^^^^^^^^^^^^^^^
  File "/root/.venv/lib/python3.11/site-packages/telegram/ext/_updater.py", line 371, in polling_action_cb
    updates = await self.bot.get_updates(
              ^^^^^^^^^^^^^^^^^^^^^^^^^^^
  File "/root/.venv/lib/python3.11/site-packages/telegram/ext/_extbot.py", line 650, in get_updates
    updates = await super().get_updates(
              ^^^^^^^^^^^^^^^^^^^^^^^^^^
  File "/root/.venv/lib/python3.11/site-packages/telegram/_bot.py", line 4480, in get_updates
    await self._post(
  File "/root/.venv/lib/python3.11/site-packages/telegram/_bot.py", line 619, in _post
    return await self._do_post(
           ^^^^^^^^^^^^^^^^^^^^
  File "/root/.venv/lib/python3.11/site-packages/telegram/ext/_extbot.py", line 354, in _do_post
    return await super()._do_post(
           ^^^^^^^^^^^^^^^^^^^^^^^
  File "/root/.venv/lib/python3.11/site-packages/telegram/_bot.py", line 648, in _do_post
    result = await request.post(
             ^^^^^^^^^^^^^^^^^^^
  File "/root/.venv/lib/python3.11/site-packages/telegram/request/_baserequest.py", line 202, in post
    result = await self._request_wrapper(
             ^^^^^^^^^^^^^^^^^^^^^^^^^^^^
  File "/root/.venv/lib/python3.11/site-packages/telegram/request/_baserequest.py", line 385, in _request_wrapper
    raise Conflict(message)
telegram.error.Conflict: Conflict: terminated by other getUpdates request; make sure that only one bot instance is running
Exception happened while polling for updates.
Traceback (most recent call last):
  File "/root/.venv/lib/python3.11/site-packages/telegram/ext/_updater.py", line 750, in _network_loop_retry
    if not await do_action():
           ^^^^^^^^^^^^^^^^^
  File "/root/.venv/lib/python3.11/site-packages/telegram/ext/_updater.py", line 744, in do_action
    return action_cb_task.result()
           ^^^^^^^^^^^^^^^^^^^^^^^
  File "/root/.venv/lib/python3.11/site-packages/telegram/ext/_updater.py", line 371, in polling_action_cb
    updates = await self.bot.get_updates(
              ^^^^^^^^^^^^^^^^^^^^^^^^^^^
  File "/root/.venv/lib/python3.11/site-packages/telegram/ext/_extbot.py", line 650, in get_updates
    updates = await super().get_updates(
              ^^^^^^^^^^^^^^^^^^^^^^^^^^
  File "/root/.venv/lib/python3.11/site-packages/telegram/_bot.py", line 4480, in get_updates
    await self._post(
  File "/root/.venv/lib/python3.11/site-packages/telegram/_bot.py", line 619, in _post
    return await self._do_post(
           ^^^^^^^^^^^^^^^^^^^^
  File "/root/.venv/lib/python3.11/site-packages/telegram/ext/_extbot.py", line 354, in _do_post
    return await super()._do_post(
           ^^^^^^^^^^^^^^^^^^^^^^^
  File "/root/.venv/lib/python3.11/site-packages/telegram/_bot.py", line 648, in _do_post
    result = await request.post(
             ^^^^^^^^^^^^^^^^^^^
  File "/root/.venv/lib/python3.11/site-packages/telegram/request/_baserequest.py", line 202, in post
    result = await self._request_wrapper(
             ^^^^^^^^^^^^^^^^^^^^^^^^^^^^
  File "/root/.venv/lib/python3.11/site-packages/telegram/request/_baserequest.py", line 385, in _request_wrapper
    raise Conflict(message)
telegram.error.Conflict: Conflict: terminated by other getUpdates request; make sure that only one bot instance is running
